Workbook

Sheet Assumptions
F2: Historical | I2: Projected
B3: Three-Statement Assumptions | D3: Units | F3: FY 20 | G3: FY 21 | H3: FY 22 | I3: FY 23 | J3: FY 24 | K3: FY 25 | L3: FY 26 | M3: FY 27 | N3: FY 28 | O3: FY 29 | P3: FY 30 | Q3: FY 31 | R3: FY 32 | S3: FY 33
B4: Income Statement Drivers
B6: Service costs as a % of revenue | D6: % | I6: 0.15 | J6: 0.14 | K6: 0.13 | L6: 0.12 | M6: 0.12 | N6: 0.12 | O6: 0.12 | P6: 0.12 | Q6: 0.12 | R6: 0.12 | S6: 0.12
B7: R&D as a % of revenue | D7: % | F7: ='Income Statement'!E20/'Income Statement'!E9 -> 0.33626904 | G7: ='Income Statement'!F20/'Income Statement'!F9 -> 0.37564477 | H7: ='Income Statement'!G20/'Income Statement'!G9 -> 0.34241751 | I7: 0.32 | J7: 0.3 | K7: 0.28 | L7: 0.26 | M7: 0.24 | N7: 0.22 | O7: 0.2 | P7: 0.2 | Q7: 0.2 | R7: 0.2 | S7: 0.2
B8: General and administrative as a % of revenue | D8: % | F8: ='Income Statement'!E22/'Income Statement'!E9 -> 0.33914975 | G8: ='Income Statement'!F22/'Income Statement'!F9 -> 0.53770382 | H8: ='Income Statement'!G22/'Income Statement'!G9 -> 0.37568443 | I8: 0.36 | J8: 0.34 | K8: 0.32 | L8: 0.3 | M8: 0.28 | N8: 0.26 | O8: 0.24 | P8: 0.24 | Q8: 0.24 | R8: 0.24 | S8: 0.24
B9: D&A | D9: % | F9: ='Income Statement'!E23/'Income Statement'!E9 -> 0.0072208122 | G9: ='Income Statement'!F23/'Income Statement'!F9 -> 0.020447821 | H9: ='Income Statement'!G23/'Income Statement'!G9 -> 0.071079306 | I9: 0.06 | J9: 0.05 | K9: 0.04 | L9: 0.03 | M9: 0.03 | N9: 0.03 | O9: 0.03 | P9: 0.03 | Q9: 0.03 | R9: 0.03 | S9: 0.03
B11: Balance Sheet Drivers
B13: Current assets:
B14: Accounts receivable, net as a % of revenue | D14: % | G14: ='Balance Sheet'!E8/'Income Statement'!F$9 -> 0.076477871 | H14: ='Balance Sheet'!F8/'Income Statement'!G$9 -> 0.037455663 | I14: =AVERAGE($G$14:$H$14) -> 0.056966767 | J14: =AVERAGE($G$14:$H$14) -> 0.056966767 | K14: =AVERAGE($G$14:$H$14) -> 0.056966767 | L14: =AVERAGE($G$14:$H$14) -> 0.056966767 | M14: =AVERAGE($G$14:$H$14) -> 0.056966767 | N14: =AVERAGE($G$14:$H$14) -> 0.056966767 | O14: =AVERAGE($G$14:$H$14) -> 0.056966767 | P14: =AVERAGE($G$14:$H$14) -> 0.056966767 | ... S14: =AVERAGE($G$14:$H$14) -> 0.056966767
B15: Acquired card receivable, net as a % of revenue | D15: % | G15: ='Balance Sheet'!E9/'Income Statement'!F$9 -> 0.61735043 | H15: ='Balance Sheet'!F9/'Income Statement'!G$9 -> 0.39938999 | I15: 0.38 | J15: 0.38 | K15: 0.38 | L15: 0.38 | M15: 0.38 | N15: 0.38 | O15: 0.38 | P15: 0.38 | Q15: 0.38 | R15: 0.38 | S15: 0.38
B16: Prepaid expenses and other current assets as a % of G&A | D16: % | G16: ='Balance Sheet'!E10/'Income Statement'!F9 -> 0.28201792 | H16: ='Balance Sheet'!F10/'Income Statement'!G9 -> 0.23561941 | I16: =AVERAGE($G$16:$H$16) -> 0.25881866 | J16: =AVERAGE($G$16:$H$16) -> 0.25881866 | K16: =AVERAGE($G$16:$H$16) -> 0.25881866 | L16: =AVERAGE($G$16:$H$16) -> 0.25881866 | M16: =AVERAGE($G$16:$H$16) -> 0.25881866 | N16: =AVERAGE($G$16:$H$16) -> 0.25881866 | O16: =AVERAGE($G$16:$H$16) -> 0.25881866 | P16: =AVERAGE($G$16:$H$16) -> 0.25881866 | ... S16: =AVERAGE($G$16:$H$16) -> 0.25881866
B18: Non-current assets:
B19: Other assets as a % of revenue | D19: % | G19: ='Balance Sheet'!E19/'Income Statement'!F9 -> 0.22212662 | H19: ='Balance Sheet'!F19/'Income Statement'!G9 -> 0.074350543 | I19: 0.07 | J19: 0.07 | K19: 0.07 | L19: 0.07 | M19: 0.07 | N19: 0.07 | O19: 0.07 | P19: 0.07 | Q19: 0.07 | R19: 0.07 | S19: 0.07
B21: Current liabilities:
B22: Accounts Payable % of COGS | D22: % | G22: ='Balance Sheet'!E27/'Income Statement'!F15 -> 0.19260266 | H22: ='Balance Sheet'!F27/'Income Statement'!G15 -> 0.068605004 | I22: =AVERAGE($G$22:$H$22) -> 0.13060383 | J22: =AVERAGE($G$22:$H$22) -> 0.13060383 | K22: =AVERAGE($G$22:$H$22) -> 0.13060383 | L22: =AVERAGE($G$22:$H$22) -> 0.13060383 | M22: =AVERAGE($G$22:$H$22) -> 0.13060383 | N22: =AVERAGE($G$22:$H$22) -> 0.13060383 | O22: =AVERAGE($G$22:$H$22) -> 0.13060383 | P22: =AVERAGE($G$22:$H$22) -> 0.13060383 | ... S22: =AVERAGE($G$22:$H$22) -> 0.13060383
B23: Accrued compensation and benefits as a % of opex | D23: % | G23: ='Balance Sheet'!E28/'Income Statement'!E24 -> 0.13289531 | H23: ='Balance Sheet'!F28/'Income Statement'!F24 -> 0.099867092 | I23: =AVERAGE($G$23:$H$23) -> 0.1163812 | J23: =AVERAGE($G$23:$H$23) -> 0.1163812 | K23: =AVERAGE($G$23:$H$23) -> 0.1163812 | L23: =AVERAGE($G$23:$H$23) -> 0.1163812 | M23: =AVERAGE($G$23:$H$23) -> 0.1163812 | N23: =AVERAGE($G$23:$H$23) -> 0.1163812 | O23: =AVERAGE($G$23:$H$23) -> 0.1163812 | P23: =AVERAGE($G$23:$H$23) -> 0.1163812 | ... S23: =AVERAGE($G$23:$H$23) -> 0.1163812
B24: Deferred Revenue as a % of revenue | D24: % | G24: ='Balance Sheet'!E29/'Income Statement'!F9 -> 0.053923153 | H24: ='Balance Sheet'!F29/'Income Statement'!G9 -> 0.0496418 | I24: =AVERAGE($G$24:$H$24) -> 0.051782476 | J24: =AVERAGE($G$24:$H$24) -> 0.051782476 | K24: =AVERAGE($G$24:$H$24) -> 0.051782476 | L24: =AVERAGE($G$24:$H$24) -> 0.051782476 | M24: =AVERAGE($G$24:$H$24) -> 0.051782476 | N24: =AVERAGE($G$24:$H$24) -> 0.051782476 | O24: =AVERAGE($G$24:$H$24) -> 0.051782476 | P24: =AVERAGE($G$24:$H$24) -> 0.051782476 | ... S24: =AVERAGE($G$24:$H$24) -> 0.051782476
B25: Other accruals and current liabilities as a % of opex | D25: % | G25: ='Balance Sheet'!E30/'Income Statement'!F24 -> 0.24798744 | H25: ='Balance Sheet'!F30/'Income Statement'!G24 -> 0.14755958 | I25: =AVERAGE($G$25:$H$25) -> 0.19777351 | J25: =AVERAGE($G$25:$H$25) -> 0.19777351 | K25: =AVERAGE($G$25:$H$25) -> 0.19777351 | L25: =AVERAGE($G$25:$H$25) -> 0.19777351 | M25: =AVERAGE($G$25:$H$25) -> 0.19777351 | N25: =AVERAGE($G$25:$H$25) -> 0.19777351 | O25: =AVERAGE($G$25:$H$25) -> 0.19777351 | P25: =AVERAGE($G$25:$H$25) -> 0.19777351 | ... S25: =AVERAGE($G$25:$H$25) -> 0.19777351
B26: Funds held for customers as a % of TPV | D26: % | G26: ='Balance Sheet'!E11/Assumptions!G39 -> 0.015741518 | H26: ='Balance Sheet'!F11/(Assumptions!H39+Assumptions!H43) -> 0.013541279 | I26: 0.0135 | J26: 0.0135 | K26: 0.0135 | L26: 0.0135 | M26: 0.0135 | N26: 0.0135 | O26: 0.0135 | P26: 0.0135 | Q26: 0.0135 | R26: 0.0135 | S26: 0.0135
B28: Non-current liabilities:
B29: Deferred revenue as a % of revenue | D29: % | G29: ='Balance Sheet'!E36/'Income Statement'!F9 -> 0.012280444 | H29: ='Balance Sheet'!F36/'Income Statement'!G9 -> 0.0033631431 | I29: =AVERAGE($G$29:$H$29) -> 0.0078217936 | J29: =AVERAGE($G$29:$H$29) -> 0.0078217936 | K29: =AVERAGE($G$29:$H$29) -> 0.0078217936 | L29: =AVERAGE($G$29:$H$29) -> 0.0078217936 | M29: =AVERAGE($G$29:$H$29) -> 0.0078217936 | N29: =AVERAGE($G$29:$H$29) -> 0.0078217936 | O29: =AVERAGE($G$29:$H$29) -> 0.0078217936 | P29: =AVERAGE($G$29:$H$29) -> 0.0078217936 | ... S29: =AVERAGE($G$29:$H$29) -> 0.0078217936
F31: Historical | I31: Projected
A32: Purchase of PPE | B32: Revenue Build Assumptions | D32: Units | F32: FY 20 | G32: FY 21 | H32: FY 22 | I32: FY 23 | J32: FY 24 | K32: FY 25 | L32: FY 26 | M32: FY 27 | N32: FY 28 | O32: FY 29 | P32: FY 30 | Q32: FY 31 | R32: FY 32 | S32: FY 33
B33: Subscription Revenue
B35: Bill customer retention rate | D35: % | H35: 0.86 | I35: 0.86 | J35: 0.86 | K35: 0.87 | L35: 0.87 | M35: 0.87 | N35: 0.87 | O35: 0.88 | P35: 0.88 | Q35: 0.88 | R35: 0.88 | S35: 0.88
B37: Transaction Revenue
B39: Bill TPV | D39: $ | G39: 140304000 | H39: 219080000 | I39: ='Revenue Build'!E16 -> 205600000 | J39: ='Revenue Build'!F16 -> 268678080 | K39: ='Revenue Build'!G16 -> 3.5110851e+08 | L39: ='Revenue Build'!H16 -> 4.4366072e+08 | M39: ='Revenue Build'!I16 -> 5.6060969e+08 | N39: ='Revenue Build'!J16 -> 7.083864e+08 | O39: ='Revenue Build'!K16 -> 8.9511705e+08 | P39: ='Revenue Build'!L16 -> 1.0721712e+09 | ... S39: ='Revenue Build'!O16 -> 1.8077757e+09
B40: Bill take rate | D40: % | H40: =83/64000 -> 0.001296875 | I40: =83/64000 -> 0.001296875 | J40: =83/64000 -> 0.001296875 | K40: =83/64000 -> 0.001296875 | L40: =83/64000 -> 0.001296875 | M40: =83/64000 -> 0.001296875 | N40: =83/64000 -> 0.001296875 | O40: =83/64000 -> 0.001296875 | ... S40: =83/64000 -> 0.001296875
B42: Divvy customer retention rate | D42: % | I42: 0.86 | J42: 0.86 | K42: 0.87 | L42: 0.87 | M42: 0.87 | N42: 0.87 | O42: 0.88 | P42: 0.88 | Q42: 0.88 | R42: 0.88 | S42: 0.88
B43: TPV | D43: $ | H43: 13000000 | I43: ='Revenue Build'!E22 -> 16270200 | J43: ='Revenue Build'!F22 -> 22103067 | K43: ='Revenue Build'!G22 -> 27690722 | L43: ='Revenue Build'!H22 -> 34989996 | M43: ='Revenue Build'!I22 -> 42323899 | N43: ='Revenue Build'!J22 -> 50246933 | O43: ='Revenue Build'!K22 -> 59653159 | P43: ='Revenue Build'!L22 -> 71452554 | ... S43: ='Revenue Build'!O22 -> 1.0902136e+08
B44: Take rate | D44: % | H44: =86.6/3300 -> 0.026242424 | I44: 0.026242424 | J44: 0.026242424 | K44: 0.026242424 | L44: 0.026242424 | M44: 0.026242424 | N44: 0.026242424 | O44: 0.026242424 | P44: 0.026242424 | Q44: 0.026242424 | R44: 0.026242424 | S44: 0.026242424
B46: Interest Revenue from Funds
B48: Revenue as a % of funds | D48: % | G48: ='Income Statement'!F8/'Balance Sheet'!E11 -> 0.0027211833 | H48: ='Income Statement'!G8/'Balance Sheet'!F11 -> 0.0027346261 | I48: 0.03 | J48: 0.03 | K48: 0.03 | L48: 0.03 | M48: 0.03 | N48: 0.03 | O48: 0.03 | P48: 0.03 | Q48: 0.03 | R48: 0.03 | S48: 0.03
F50: Historical | I50: Projected
B51: D&A and PPE Assumptions | D51: Units | F51: FY 20 | G51: FY 21 | H51: FY 22 | I51: FY 23 | J51: FY 24 | K51: FY 25 | L51: FY 26 | M51: FY 27 | N51: FY 28 | O51: FY 29 | P51: FY 30 | Q51: FY 31 | R51: FY 32 | S51: FY 33
B52: Depreciation and Amortization Schedule
B54: Depreciation Expense | D54: $ | H54: 3252 | I54: =I55*'Revenue Build'!E36 -> 5364.463 | J54: =J55*'Revenue Build'!F36 -> 6988.7316 | K54: =K55*'Revenue Build'!G36 -> 9814.7127 | L54: =L55*'Revenue Build'!H36 -> 12116.412 | M54: =M55*'Revenue Build'!I36 -> 15764.964 | N54: =N55*'Revenue Build'!J36 -> 18995.66 | O54: =O55*'Revenue Build'!K36 -> 22913.218 | P54: =P55*'Revenue Build'!L36 -> 28575.579 | ... S54: =S55*'Revenue Build'!O36 -> 44279.05
B55: % of revenue | D55: % | H55: =H54/'Income Statement'!G9 -> 0.0050657441 | I55: =H55 -> 0.0050657441 | J55: =I55 -> 0.0050657441 | K55: =J55 -> 0.0050657441 | L55: =K55 -> 0.0050657441 | M55: =L55 -> 0.0050657441 | N55: =M55 -> 0.0050657441 | O55: =N55 -> 0.0050657441 | P55: =O55 -> 0.0050657441 | ... S55: =R55 -> 0.0050657441
B57: PP&E Schedule
...

Sheet Revenue Build
E2: Projected
B3: Revenue Build | D3: Units | E3: FY 23 | F3: FY 24 | G3: FY 25 | H3: FY 26 | I3: FY 27 | J3: FY 28 | K3: FY 29 | L3: FY 30 | M3: FY 31 | N3: FY 32 | O3: FY 33
B4: Subscription Revenue
B6: Bill + Invoice2go customers | D6: # | E6: =Assumptions!F94 -> 411200 | F6: =Assumptions!G94 -> 497552 | G6: =Assumptions!H94 -> 602037.92 | H6: =Assumptions!I94 -> 704384.37 | I6: =Assumptions!J94 -> 824129.71 | J6: =Assumptions!K94 -> 964231.76 | K6: =Assumptions!L94 -> 1128151.2 | L6: =Assumptions!M94 -> 1274810.8 | ... O6: =Assumptions!P94 -> 1839420.7
B7: BILL + Invoice2go subscription per customer | D7: $ | E7: =Assumptions!F100 -> 0.67 | F7: =Assumptions!G100 -> 0.67 | G7: =Assumptions!H100 -> 1 | H7: =Assumptions!I100 -> 1 | I7: =Assumptions!J100 -> 1.25 | J7: =Assumptions!K100 -> 1.25 | K7: =Assumptions!L100 -> 1.25 | L7: =Assumptions!M100 -> 1.5 | ... O7: =Assumptions!P100 -> 1.5
B8: Bill transaction revenue | D8: $ | E8: =E6*E7 -> 275504 | F8: =F6*F7 -> 333359.84 | G8: =G6*G7 -> 602037.92 | H8: =H6*H7 -> 704384.37 | I8: =I6*I7 -> 1030162.1 | J8: =J6*J7 -> 1205289.7 | K8: =K6*K7 -> 1410188.9 | L8: =L6*L7 -> 1912216.2 | ... O8: =O6*O7 -> 2759131
B10: Total subscription revenue | D10: $ | E10: =E8 -> 275504 | F10: =F8 -> 333359.84 | G10: =G8 -> 602037.92 | H10: =H8 -> 704384.37 | I10: =I8 -> 1030162.1 | J10: =J8 -> 1205289.7 | K10: =K8 -> 1410188.9 | L10: =L8 -> 1912216.2 | ... O10: =O8 -> 2759131
B12: Transaction Revenue
B14: Bill + Invoice2go customers | D14: # | E14: =Assumptions!F94 -> 411200 | F14: =Assumptions!G94 -> 497552 | G14: =Assumptions!H94 -> 602037.92 | H14: =Assumptions!I94 -> 704384.37 | I14: =Assumptions!J94 -> 824129.71 | J14: =Assumptions!K94 -> 964231.76 | K14: =Assumptions!L94 -> 1128151.2 | L14: =Assumptions!M94 -> 1274810.8 | ... O14: =Assumptions!P94 -> 1839420.7
B15: Bill TPV per customer | D15: $ | E15: =Assumptions!F108 -> 500 | F15: =Assumptions!G108 -> 540 | G15: =Assumptions!H108 -> 583.2 | H15: =Assumptions!I108 -> 629.856 | I15: =Assumptions!J108 -> 680.24448 | J15: =Assumptions!K108 -> 734.66404 | K15: =Assumptions!L108 -> 793.43716 | L15: =Assumptions!M108 -> 841.04339 | ... O15: =Assumptions!P108 -> 982.79621
B16: Bill TPV | D16: $ | E16: =E14*E15 -> 205600000 | F16: =F14*F15 -> 268678080 | G16: =G14*G15 -> 3.5110851e+08 | H16: =H14*H15 -> 4.4366072e+08 | I16: =I14*I15 -> 5.6060969e+08 | J16: =J14*J15 -> 7.083864e+08 | K16: =K14*K15 -> 8.9511705e+08 | L16: =L14*L15 -> 1.0721712e+09 | ... O16: =O14*O15 -> 1.8077757e+09
B17: Bill TPV take rate | D17: % | E17: 0.001296875 | F17: 0.001296875 | G17: 0.001296875 | H17: 0.001296875 | I17: 0.001296875 | J17: 0.001296875 | K17: 0.001296875 | L17: 0.001296875 | M17: 0.001296875 | N17: 0.001296875 | O17: 0.001296875
B18: Bill transaction revenue | D18: $ | E18: =E14*E15*E17 -> 266637.5 | F18: =F14*F15*F17 -> 348441.89 | G18: =G14*G15*G17 -> 455343.86 | H18: =H14*H15*H17 -> 575372.5 | I18: =I14*I15*I17 -> 727040.69 | J18: =J14*J15*J17 -> 918688.61 | K18: =K14*K15*K17 -> 1160854.9 | L18: =L14*L15*L17 -> 1390472 | ... O18: =O14*O15*O17 -> 2344459.1
B20: Divvy customers | D20: # | E20: =Assumptions!F120 -> 27117 | F20: =Assumptions!G120 -> 33489.495 | G20: =Assumptions!H120 -> 38847.814 | H20: =Assumptions!I120 -> 45451.943 | I20: =Assumptions!J120 -> 50906.176 | J20: =Assumptions!K120 -> 57014.917 | K20: =Assumptions!L120 -> 63856.707 | L20: =Assumptions!M120 -> 72158.079 | ... O20: =Assumptions!P120 -> 95106.657
B21: Divvy TPV per customer | D21: $ | E21: =Assumptions!F114 -> 600 | F21: =Assumptions!G114 -> 660 | G21: =Assumptions!H114 -> 712.8 | H21: =Assumptions!I114 -> 769.824 | I21: =Assumptions!J114 -> 831.40992 | J21: =Assumptions!K114 -> 881.29452 | K21: =Assumptions!L114 -> 934.17219 | L21: =Assumptions!M114 -> 990.22252 | ... O21: =Assumptions!P114 -> 1146.3063
B22: Divvy TPV | D22: $ | E22: =E21*E20 -> 16270200 | F22: =F21*F20 -> 22103067 | G22: =G21*G20 -> 27690722 | H22: =H21*H20 -> 34989996 | I22: =I21*I20 -> 42323899 | J22: =J21*J20 -> 50246933 | K22: =K21*K20 -> 59653159 | L22: =L21*L20 -> 71452554 | ... O22: =O21*O20 -> 1.0902136e+08
B23: Divvy TPV take rate | D23: % | E23: 0.026242424 | F23: 0.026242424 | G23: 0.026242424 | H23: 0.026242424 | I23: 0.026242424 | J23: 0.026242424 | K23: 0.026242424 | L23: 0.026242424 | M23: 0.026242424 | N23: 0.026242424 | O23: 0.026242424
B24: Divvy transaction revenue | D24: $ | E24: =E20*E21*E23 -> 426969.49 | F24: =F20*F21*F23 -> 580038.05 | G24: =G20*G21*G23 -> 726671.67 | H24: =H20*H21*H23 -> 918222.33 | I24: =I20*I21*I23 -> 1110681.7 | J24: =J20*J21*J23 -> 1318601.3 | K24: =K20*K21*K23 -> 1565443.5 | L24: =L20*L21*L23 -> 1875088.2 | ... O24: =O20*O21*O23 -> 2860984.9
B26: Total transaction revenue | D26: $ | E26: =E24+E18 -> 693606.99 | F26: =F24+F18 -> 928479.94 | G26: =G24+G18 -> 1182015.5 | H26: =H24+H18 -> 1493594.8 | I26: =I24+I18 -> 1837722.4 | J26: =J24+J18 -> 2237290 | K26: =K24+K18 -> 2726298.4 | L26: =L24+L18 -> 3265560.3 | ... O26: =O24+O18 -> 5205444
B28: Interest on funds held for customers
B30: Funds held for customers | D30: $ | E30: ='Balance Sheet'!G11 -> 2995247.7 | F30: ='Balance Sheet'!H11 -> 3925545.5 | G30: ='Balance Sheet'!I11 -> 5113789.7 | H30: ='Balance Sheet'!J11 -> 6461784.7 | I30: ='Balance Sheet'!K11 -> 8139603.4 | J30: ='Balance Sheet'!L11 -> 10241550 | K30: ='Balance Sheet'!M11 -> 12889398 | L30: ='Balance Sheet'!N11 -> 15438921 | ... O30: ='Balance Sheet'!Q11 -> 25876760
B31: Interest rate on funds | D31: % | E31: =Assumptions!I48 -> 0.03 | F31: =Assumptions!J48 -> 0.03 | G31: =Assumptions!K48 -> 0.03 | H31: =Assumptions!L48 -> 0.03 | I31: =Assumptions!M48 -> 0.03 | J31: =Assumptions!N48 -> 0.03 | K31: =Assumptions!O48 -> 0.03 | L31: =Assumptions!P48 -> 0.03 | ... O31: =Assumptions!S48 -> 0.03
B32: Interest income | D32: $ | E32: =E30*E31 -> 89857.431 | F32: =F30*F31 -> 117766.36 | G32: =G30*G31 -> 153413.69 | H32: =H30*H31 -> 193853.54 | I32: =I30*I31 -> 244188.1 | J32: =J30*J31 -> 307246.5 | K32: =K30*K31 -> 386681.94 | L32: =L30*L31 -> 463167.62 | ... O32: =O30*O31 -> 776302.8
B34: Total fund revenue | D34: $ | E34: =E32 -> 89857.431 | F34: =F32 -> 117766.36 | G34: =G32 -> 153413.69 | H34: =H32 -> 193853.54 | I34: =I32 -> 244188.1 | J34: =J32 -> 307246.5 | K34: =K32 -> 386681.94 | L34: =L32 -> 463167.62 | ... O34: =O32 -> 776302.8
B36: Total revenue | D36: $ | E36: =E10+E26+E34 -> 1058968.4 | F36: =F10+F26+F34 -> 1379606.1 | G36: =G10+G26+G34 -> 1937467.1 | H36: =H10+H26+H34 -> 2391832.7 | I36: =I10+I26+I34 -> 3112072.6 | J36: =J10+J26+J34 -> 3749826.2 | K36: =K10+K26+K34 -> 4523169.3 | L36: =L10+L26+L34 -> 5640944.1 | ... O36: =O10+O26+O34 -> 8740877.8

Sheet Income Statement
E2: Historical | H2: Projected
B3: Income Statement | D3: Units | E3: FY 20 | F3: FY 21 | G3: FY 22 | H3: FY 23 | I3: FY 24 | J3: FY 25 | K3: FY 26 | L3: FY 27 | M3: FY 28 | N3: FY 29 | O3: FY 30 | P3: FY 31 | Q3: FY 32 | R3: FY 33
B5: Revenue:
B6: Small-to-midsize business, accounting firm customers and other | D6: $M | E6: 126035 | F6: 218227 | G6: 603171 | H6: 899100 | I6: 0 | J6: 0 | K6: 0 | L6: 0 | M6: 0 | N6: 0 | O6: 0 | P6: 0 | Q6: 0 | R6: 0
B7: Financial institution customers | D7: $M | E7: 10370 | F7: 14028 | G7: 30194 | H7: 99900 | I7: 0 | J7: 0 | K7: 0 | L7: 0 | M7: 0 | N7: 0 | O7: 0 | P7: 0 | Q7: 0 | R7: 0
B8: Interest on funds held for customers | D8: $M | E8: 21195 | F8: 6010 | G8: 8594 | H8: 0 | I8: ='Revenue Build'!F34 -> 117766.36 | J8: ='Revenue Build'!G34 -> 153413.69 | K8: ='Revenue Build'!H34 -> 193853.54 | L8: ='Revenue Build'!I34 -> 244188.1 | M8: ='Revenue Build'!J34 -> 307246.5 | N8: ='Revenue Build'!K34 -> 386681.94 | O8: ='Revenue Build'!L34 -> 463167.62 | P8: ='Revenue Build'!M34 -> 554455.18 | ... R8: ='Revenue Build'!O34 -> 776302.8
B9: Total revenue | D9: $M | E9: =SUM(E6:E8) -> 157600 | F9: =SUM(F6:F8) -> 238265 | G9: =SUM(G6:G8) -> 641959 | H9: =SUM(H6:H8) -> 999000 | I9: ='Revenue Build'!F36 -> 1379606.1 | J9: ='Revenue Build'!G36 -> 1937467.1 | K9: ='Revenue Build'!H36 -> 2391832.7 | L9: ='Revenue Build'!I36 -> 3112072.6 | M9: ='Revenue Build'!J36 -> 3749826.2 | N9: ='Revenue Build'!K36 -> 4523169.3 | O9: ='Revenue Build'!L36 -> 5640944.1 | P9: ='Revenue Build'!M36 -> 6605559.1 | ... R9: ='Revenue Build'!O36 -> 8740877.8
B11: Cost of Revenue:
B12: Service costs | D12: $M | E12: 37049 | F12: 56576 | G12: 105496 | H12: =H9*Assumptions!I6 -> 149850 | I12: =I9*Assumptions!J6 -> 193144.86 | J12: =J9*Assumptions!K6 -> 251870.73 | K12: =K9*Assumptions!L6 -> 287019.93 | L12: =L9*Assumptions!M6 -> 373448.72 | M12: =M9*Assumptions!N6 -> 449979.14 | N12: =N9*Assumptions!O6 -> 542780.32 | O12: =O9*Assumptions!P6 -> 676913.29 | ... R12: =R9*Assumptions!S6 -> 1048905.3
B13: Depreciation | D13: $M | E13: 0 | F13: 0 | G13: 0 | H13: =Assumptions!I54 -> 5364.463 | I13: =Assumptions!J54 -> 6988.7316 | J13: =Assumptions!K54 -> 9814.7127 | K13: =Assumptions!L54 -> 12116.412 | L13: =Assumptions!M54 -> 15764.964 | M13: =Assumptions!N54 -> 18995.66 | N13: =Assumptions!O54 -> 22913.218 | O13: =Assumptions!P54 -> 28575.579 | ... R13: =Assumptions!S54 -> 44279.05
B14: Amortization of intangible assets | D14: $M | E14: 2095 | F14: 5230 | G14: 39508 | H14: =Assumptions!I66 -> 35744.468 | I14: =Assumptions!J66 -> 35744.468 | J14: =Assumptions!K66 -> 33568 | K14: =Assumptions!L66 -> 31906 | L14: =Assumptions!M66 -> 29237 | M14: =Assumptions!N66 -> 20000 | N14: =Assumptions!O66 -> 15000 | O14: =Assumptions!P66 -> 10000 | ... R14: =Assumptions!S66 -> 5000
B15: Total cost of revenue | D15: $M | E15: =SUM(E12:E14) -> 39144 | F15: =SUM(F12:F14) -> 61806 | G15: =SUM(G12:G14) -> 145004 | H15: =SUM(H12:H14) -> 190958.93 | I15: =SUM(I12:I14) -> 235878.06 | J15: =SUM(J12:J14) -> 295253.44 | K15: =SUM(K12:K14) -> 331042.34 | L15: =SUM(L12:L14) -> 418450.68 | ... R15: =SUM(R12:R14) -> 1098184.4
B17: Gross margin | D17: $M | E17: =E9-E15 -> 118456 | F17: =F9-F15 -> 176459 | G17: =G9-G15 -> 496955 | H17: =H9-H15 -> 808041.07 | I17: =I9-I15 -> 1143728.1 | J17: =J9-J15 -> 1642213.7 | K17: =K9-K15 -> 2060790.4 | L17: =L9-L15 -> 2693622 | ... R17: =R9-R15 -> 7642693.4
B19: Operating expenses:
B20: Research and development | D20: $M | E20: 52996 | F20: 89503 | G20: 219818 | H20: =H9*Assumptions!I7 -> 319680 | I20: =I9*Assumptions!J7 -> 413881.84 | J20: =J9*Assumptions!K7 -> 542490.8 | K20: =K9*Assumptions!L7 -> 621876.51 | L20: =L9*Assumptions!M7 -> 746897.44 | M20: =M9*Assumptions!N7 -> 824961.75 | N20: =N9*Assumptions!O7 -> 904633.87 | O20: =O9*Assumptions!P7 -> 1128188.8 | ... R20: =R9*Assumptions!S7 -> 1748175.6
B21: Sales and marketing | D21: $M | E21: 45070 | F21: 67935 | G21: 307151 | H21: =Assumptions!I77 -> 220055.89 | I21: =Assumptions!J77 -> 241045.69 | J21: =Assumptions!K77 -> 283304.61 | K21: =Assumptions!L77 -> 308315.5 | L21: =Assumptions!M77 -> 358186.59 | M21: =Assumptions!N77 -> 418112.15 | N21: =Assumptions!O77 -> 476683.56 | O21: =Assumptions!P77 -> 493431.82 | ... R21: =Assumptions!S77 -> 705357.54
B22: General and administrative | D22: $M | E22: 53450 | F22: 128116 | G22: 241174 | H22: =H9*Assumptions!I8 -> 359640 | I22: =I9*Assumptions!J8 -> 469066.09 | J22: =J9*Assumptions!K8 -> 619989.48 | K22: =K9*Assumptions!L8 -> 717549.82 | L22: =L9*Assumptions!M8 -> 871380.34 | M22: =M9*Assumptions!N8 -> 974954.8 | N22: =N9*Assumptions!O8 -> 1085560.6 | O22: =O9*Assumptions!P8 -> 1353826.6 | ... R22: =R9*Assumptions!S8 -> 2097810.7
B23: Depreciation and amortization | D23: $M | E23: 1138 | F23: 4872 | G23: 45630 | H23: =H9*Assumptions!I9 -> 59940 | I23: =I9*Assumptions!J9 -> 68980.307 | J23: =J9*Assumptions!K9 -> 77498.686 | K23: =K9*Assumptions!L9 -> 71754.982 | L23: =L9*Assumptions!M9 -> 93362.179 | M23: =M9*Assumptions!N9 -> 112494.78 | N23: =N9*Assumptions!O9 -> 135695.08 | O23: =O9*Assumptions!P9 -> 169228.32 | ... R23: =R9*Assumptions!S9 -> 262226.33
B24: Total operating expenses | D24: $M | E24: =SUM(E20:E23) -> 152654 | F24: =SUM(F20:F23) -> 290426 | G24: =SUM(G20:G23) -> 813773 | H24: =SUM(H20:H23) -> 959315.89 | I24: =SUM(I20:I23) -> 1192973.9 | J24: =SUM(J20:J23) -> 1523283.6 | K24: =SUM(K20:K23) -> 1719496.8 | L24: =SUM(L20:L23) -> 2069826.6 | ... R24: =SUM(R20:R23) -> 4813570.1
B26: Operating income | D26: $M | E26: =E17-E24 -> -34198 | F26: =F17-F24 -> -113967 | G26: =G17-G24 -> -316818 | H26: =H17-H24 -> -151274.82 | I26: =I17-I24 -> -49245.842 | J26: =J17-J24 -> 118930.12 | K26: =K17-K24 -> 341293.57 | L26: =L17-L24 -> 623795.42 | ... R26: =R17-R24 -> 2829123.3
B28: Non-operating income (expense) | D28: $M | E28: 3160 | F28: -25370 | G28: -13861 | H28: 0 | I28: 0 | J28: 0 | K28: 0 | L28: 0 | M28: 0 | N28: 0 | O28: 0 | P28: 0 | Q28: 0 | R28: 0
B30: Pre-tax income | D30: $M | E30: =E26+E28 -> -31038 | F30: =F26+F28 -> -139337 | G30: =G26+G28 -> -330679 | H30: =H26+H28 -> -151274.82 | I30: =I26+I28 -> -49245.842 | J30: =J26+J28 -> 118930.12 | K30: =K26+K28 -> 341293.57 | L30: =L26+L28 -> 623795.42 | ... R30: =R26+R28 -> 2829123.3
B31: (Benefit from) provision for income taxes | D31: $M | E31: 53 | F31: -40617 | G31: -4318 | H31: =H30*0.21 -> -31767.713 | I31: =I30*0.21 -> -10341.627 | J31: =J30*0.21 -> 24975.325 | K31: =K30*0.21 -> 71671.651 | L31: =L30*0.21 -> 130997.04 | M31: =M30*0.21 -> 195368.85 | N31: =N30*0.21 -> 281379.56 | O31: =O30*0.21 -> 373963.74 | ... R31: =R30*0.21 -> 594115.9
B32: (Net Loss) Gain | D32: $M | E32: =E30-E31 -> -31091 | F32: =F30-F31 -> -98720 | G32: =G30-G31 -> -326361 | H32: =H30-H31 -> -119507.11 | I32: =I30-I31 -> -38904.215 | J32: =J30-J31 -> 93954.793 | K32: =K30-K31 -> 269621.92 | L32: =L30-L31 -> 492798.38 | ... R32: =R30-R31 -> 2235007.4

Sheet Balance Sheet
E2: Historical | G2: Projected
B3: Balance Sheet | D3: Units | E3: FY 21 | F3: FY 22 | G3: FY 23 | H3: FY 24 | I3: FY 25 | J3: FY 26 | K3: FY 27 | L3: FY 28 | M3: FY 29 | N3: FY 30 | O3: FY 31 | P3: FY 32 | Q3: FY 33
B4: Assets
B5: Current assets:
B6: Cash and cash equivalents | D6: $M | E6: 509615 | F6: 1596542 | G6: ='Balance Sheet'!F6+'Cash Flow Statement'!G62 -> 1776395.7 | H6: =G6+'Cash Flow Statement'!H62 -> 1765337.4 | I6: =H6+'Cash Flow Statement'!I62 -> 1850795 | J6: =I6+'Cash Flow Statement'!J62 -> 2071055.3 | K6: =J6+'Cash Flow Statement'!K62 -> 2505071.4 | L6: =K6+'Cash Flow Statement'!L62 -> 3123781.9 | M6: =L6+'Cash Flow Statement'!M62 -> 3983926.5 | N6: =M6+'Cash Flow Statement'!N62 -> 5216021.5 | O6: =N6+'Cash Flow Statement'!O62 -> 6671096.9 | ... Q6: =P6+'Cash Flow Statement'!Q62 -> 10315189
B7: Short-term investments | D7: $M | E7: 655314 | F7: 1108493 | G7: =F7 -> 1108493 | H7: 1108493 | I7: 1108493 | J7: 1108493 | K7: 1108493 | L7: 1108493 | M7: 1108493 | N7: 1108493 | O7: 1108493 | P7: 1108493 | Q7: 1108493
B8: Accounts receivable, net | D8: $M | E8: 18222 | F8: 24045 | G8: ='Income Statement'!H9*Assumptions!$J$14 -> 56909.8 | H8: ='Income Statement'!I9*Assumptions!$J$14 -> 78591.702 | I8: ='Income Statement'!J9*Assumptions!$J$14 -> 110371.24 | J8: ='Income Statement'!K9*Assumptions!$J$14 -> 136254.98 | K8: ='Income Statement'!L9*Assumptions!$J$14 -> 177284.72 | L8: ='Income Statement'!M9*Assumptions!$J$14 -> 213615.47 | M8: ='Income Statement'!N9*Assumptions!$J$14 -> 257670.33 | N8: ='Income Statement'!O9*Assumptions!$J$14 -> 321346.35 | ... Q8: ='Income Statement'!R9*Assumptions!$J$14 -> 497939.55
B9: Acquired card receivables, net | D9: $M | E9: 147093 | F9: 256392 | G9: =Assumptions!I88 -> 235044.72 | H9: =Assumptions!J88 -> 308047.55 | I9: =Assumptions!K88 -> 401292.1 | J9: =Assumptions!L88 -> 507072.7 | K9: =Assumptions!M88 -> 638735.41 | L9: =Assumptions!N88 -> 803680.51 | M9: =Assumptions!O88 -> 1011463.9 | N9: =Assumptions!P88 -> 1211531.4 | ... Q9: =Assumptions!S88 -> 2030615.3
B10: Prepaid expenses and other current assets | D10: $M | E10: 67195 | F10: 151258 | G10: =Assumptions!$J$16*'Income Statement'!H22 -> 93081.545 | H10: =Assumptions!$J$16*'Income Statement'!I22 -> 121403.06 | I10: =Assumptions!$J$16*'Income Statement'!J22 -> 160464.85 | J10: =Assumptions!$J$16*'Income Statement'!K22 -> 185715.29 | K10: =Assumptions!$J$16*'Income Statement'!L22 -> 225529.5 | L10: =Assumptions!$J$16*'Income Statement'!M22 -> 252336.5 | M10: =Assumptions!$J$16*'Income Statement'!N22 -> 280963.36 | N10: =Assumptions!$J$16*'Income Statement'!O22 -> 350395.59 | ... Q10: =Assumptions!$J$16*'Income Statement'!R22 -> 542952.56
B11: Funds held for customers | D11: $M | E11: 2208598 | F11: 3142660 | G11: =Assumptions!I26*(Assumptions!I39+Assumptions!I43) -> 2995247.7 | H11: =Assumptions!J26*(Assumptions!J39+Assumptions!J43) -> 3925545.5 | I11: =Assumptions!K26*(Assumptions!K39+Assumptions!K43) -> 5113789.7 | J11: =Assumptions!L26*(Assumptions!L39+Assumptions!L43) -> 6461784.7 | K11: =Assumptions!M26*(Assumptions!M39+Assumptions!M43) -> 8139603.4 | L11: =Assumptions!N26*(Assumptions!N39+Assumptions!N43) -> 10241550 | M11: =Assumptions!O26*(Assumptions!O39+Assumptions!O43) -> 12889398 | N11: =Assumptions!P26*(Assumptions!P39+Assumptions!P43) -> 15438921 | ... Q11: =Assumptions!S26*(Assumptions!S39+Assumptions!S43) -> 25876760
B12: Total current assets | D12: $M | E12: =SUM(E6:E11) -> 3606037 | F12: =SUM(F6:F11) -> 6279390 | G12: =SUM(G6:G11) -> 6265172.5 | H12: =SUM(H6:H11) -> 7307418.2 | I12: =SUM(I6:I11) -> 8745205.9 | J12: =SUM(J6:J11) -> 10470376 | K12: =SUM(K6:K11) -> 12794717 | L12: =SUM(L6:L11) -> 15743457 | ... Q12: =SUM(Q6:Q11) -> 40371949
B14: Non-current assets:
B15: Operating lease right-of-use assets, net | D15: $M | E15: 71925 | F15: 76445 | G15: =F15 -> 76445 | H15: 76445 | I15: 76445 | J15: 76445 | K15: 76445 | L15: 76445 | M15: 76445 | N15: 76445 | O15: 76445 | P15: 76445 | Q15: 76445
B16: Property and equipment, net | D16: $M | E16: 48902 | F16: 56985 | G16: =Assumptions!I62 -> 61610.537 | H16: =Assumptions!J62 -> 68417.867 | I16: =Assumptions!K62 -> 77977.825 | J16: =Assumptions!L62 -> 89779.74 | K16: =Assumptions!M62 -> 105135.5 | L16: =Assumptions!N62 -> 123638.11 | M16: =Assumptions!O62 -> 145956.58 | N16: =Assumptions!P62 -> 173790.44 | ... Q16: =Assumptions!S62 -> 287120.14
B17: Intangible assets, net | D17: $M | E17: 417341 | F17: 432583 | G17: =F17-'Cash Flow Statement'!G9 -> 353508 | H17: =G17-'Cash Flow Statement'!H9 -> 275361 | I17: =H17-'Cash Flow Statement'!I9 -> 215936 | J17: =I17-'Cash Flow Statement'!J9 -> 158173 | K17: =J17-'Cash Flow Statement'!K9 -> 103079 | L17: =K17-'Cash Flow Statement'!L9 -> 57222 | M17: =L17-'Cash Flow Statement'!M9 -> 42222 | N17: =M17-'Cash Flow Statement'!N9 -> 32222 | ... Q17: =P17-'Cash Flow Statement'!Q9 -> 17222
B18: Goodwill | D18: $M | E18: 1772043 | F18: 2362893 | G18: 2362893 | H18: 2362893 | I18: 2362893 | J18: 2362893 | K18: 2362893 | L18: 2362893 | M18: 2362893 | N18: 2362893 | O18: 2362893 | P18: 2362893 | Q18: 2362893
B19: Other assets | D19: $M | E19: 52925 | F19: 47730 | G19: ='Revenue Build'!E36*Assumptions!$I$19 -> 74127.79 | H19: ='Revenue Build'!F36*Assumptions!$I$19 -> 96572.43 | I19: ='Revenue Build'!G36*Assumptions!$I$19 -> 135622.7 | J19: ='Revenue Build'!H36*Assumptions!$I$19 -> 167428.29 | K19: ='Revenue Build'!I36*Assumptions!$I$19 -> 217845.09 | L19: ='Revenue Build'!J36*Assumptions!$I$19 -> 262487.83 | M19: ='Revenue Build'!K36*Assumptions!$I$19 -> 316621.85 | N19: ='Revenue Build'!L36*Assumptions!$I$19 -> 394866.09 | ... Q19: ='Revenue Build'!O36*Assumptions!$I$19 -> 611861.45
B20: Total non-current assets | D20: $M | E20: =SUM(E15:E19) -> 2363136 | F20: =SUM(F15:F19) -> 2976636 | G20: =SUM(G15:G19) -> 2928584.3 | H20: =SUM(H15:H19) -> 2879689.3 | I20: =SUM(I15:I19) -> 2868874.5 | J20: =SUM(J15:J19) -> 2854719 | K20: =SUM(K15:K19) -> 2865397.6 | L20: =SUM(L15:L19) -> 2882685.9 | ... Q20: =SUM(Q15:Q19) -> 3355541.6
B22: Total assets | D22: $M | E22: =E12+E20 -> 5969173 | F22: =F12+F20 -> 9256026 | G22: =G12+G20 -> 9193756.8 | H22: =H12+H20 -> 10187108 | I22: =I12+I20 -> 11614080 | J22: =J12+J20 -> 13325095 | K22: =K12+K20 -> 15660115 | L22: =L12+L20 -> 18626143 | ... Q22: =Q12+Q20 -> 43727491
B25: Liabilities
B26: Current liabilities:
B27: Accounts payable | D27: $M | E27: 11904 | F27: 9948 | G27: ='Income Statement'!H15*Assumptions!$J$22 -> 24939.968 | H27: ='Income Statement'!I15*Assumptions!$J$22 -> 30806.578 | I27: ='Income Statement'!J15*Assumptions!$J$22 -> 38561.231 | J27: ='Income Statement'!K15*Assumptions!$J$22 -> 43235.398 | K27: ='Income Statement'!L15*Assumptions!$J$22 -> 54651.262 | L27: ='Income Statement'!M15*Assumptions!$J$22 -> 63861.982 | M27: ='Income Statement'!N15*Assumptions!$J$22 -> 75840.801 | N27: ='Income Statement'!O15*Assumptions!$J$22 -> 93445.589 | ... Q27: ='Income Statement'!R15*Assumptions!$J$22 -> 143427.09
B28: Accrued compensation and benefits | D28: $M | E28: 20287 | F28: 29004 | G28: ='Income Statement'!H24*Assumptions!$J$23 -> 111646.33 | H28: ='Income Statement'!I24*Assumptions!$J$23 -> 138839.74 | I28: ='Income Statement'!J24*Assumptions!$J$23 -> 177281.57 | J28: ='Income Statement'!K24*Assumptions!$J$23 -> 200117.1 | K28: ='Income Statement'!L24*Assumptions!$J$23 -> 240888.9 | L28: ='Income Statement'!M24*Assumptions!$J$23 -> 271229.12 | M28: ='Income Statement'!N24*Assumptions!$J$23 -> 302890.58 | N28: ='Income Statement'!O24*Assumptions!$J$23 -> 365981.11 | ... Q28: ='Income Statement'!R24*Assumptions!$J$23 -> 560209.06
B29: Deferred revenue | D29: $M | E29: 12848 | F29: 31868 | G29: =Assumptions!I24*'Income Statement'!H9 -> 51730.694 | H29: =Assumptions!J24*'Income Statement'!I9 -> 71439.422 | I29: =Assumptions!K24*'Income Statement'!J9 -> 100326.85 | J29: =Assumptions!L24*'Income Statement'!K9 -> 123855.02 | K29: =Assumptions!M24*'Income Statement'!L9 -> 161150.83 | L29: =Assumptions!N24*'Income Statement'!M9 -> 194175.28 | M29: =Assumptions!O24*'Income Statement'!N9 -> 234220.91 | N29: =Assumptions!P24*'Income Statement'!O9 -> 292102.05 | ... Q29: =Assumptions!S24*'Income Statement'!R9 -> 452624.3
B30: Other accruals and current liabilities | D30: $M | E30: 72022 | F30: 120080 | G30: ='Income Statement'!H24*Assumptions!$J$25 -> 189727.27 | H30: ='Income Statement'!I24*Assumptions!$J$25 -> 235938.64 | I30: ='Income Statement'!J24*Assumptions!$J$25 -> 301265.14 | J30: ='Income Statement'!K24*Assumptions!$J$25 -> 340070.92 | K30: ='Income Statement'!L24*Assumptions!$J$25 -> 409356.86 | L30: ='Income Statement'!M24*Assumptions!$J$25 -> 460915.81 | M30: ='Income Statement'!N24*Assumptions!$J$25 -> 514720.02 | N30: ='Income Statement'!O24*Assumptions!$J$25 -> 621933.52 | ... Q30: ='Income Statement'!R24*Assumptions!$J$25 -> 951996.65
B31: Borrowings from credit facilities, net | D31: $M | E31: 0 | F31: 75097 | G31: 75097 | H31: 75097 | I31: 75097 | J31: 75097 | K31: 75097 | L31: 75097 | M31: 75097 | N31: 75097 | O31: 75097 | P31: 75097 | Q31: 75097
B32: Customer fund deposits | D32: $M | E32: 2208598 | F32: 3142660 | G32: =G11 -> 2995247.7 | H32: =H11 -> 3925545.5 | I32: =I11 -> 5113789.7 | J32: =J11 -> 6461784.7 | K32: =K11 -> 8139603.4 | L32: =L11 -> 10241550 | M32: =M11 -> 12889398 | N32: =N11 -> 15438921 | ... Q32: =Q11 -> 25876760
B33: Total current liabilities | D33: $M | E33: =SUM(E27:E32) -> 2325659 | F33: =SUM(F27:F32) -> 3408657 | G33: =SUM(G27:G32) -> 3448389 | H33: =SUM(H27:H32) -> 4477666.9 | I33: =SUM(I27:I32) -> 5806321.5 | J33: =SUM(J27:J32) -> 7244160.1 | K33: =SUM(K27:K32) -> 9080748.2 | L33: =SUM(L27:L32) -> 11306829 | ... Q33: =SUM(Q27:Q32) -> 28060114
B35: Non-current liabilities:
B36: Deferred revenue | D36: $M | E36: 2926 | F36: 2159 | G36: ='Income Statement'!H9*Assumptions!I29 -> 7813.9718 | H36: ='Income Statement'!I9*Assumptions!J29 -> 10790.994 | I36: ='Income Statement'!J9*Assumptions!K29 -> 15154.468 | J36: ='Income Statement'!K9*Assumptions!L29 -> 18708.422 | K36: ='Income Statement'!L9*Assumptions!M29 -> 24341.99 | L36: ='Income Statement'!M9*Assumptions!N29 -> 29330.366 | M36: ='Income Statement'!N9*Assumptions!O29 -> 35379.297 | N36: ='Income Statement'!O9*Assumptions!P29 -> 44122.3 | ... Q36: ='Income Statement'!R9*Assumptions!S29 -> 68369.342
B37: Operating lease liabilities | D37: $M | E37: 86639 | F37: 82728 | G37: 83000 | H37: 83000 | I37: 83000 | J37: 83000 | K37: 83000 | L37: 83000 | M37: 83000 | N37: 83000 | O37: 83000 | P37: 83000 | Q37: 83000
B38: Borrowings from credit facilities, net | D38: $M | E38: 79534 | F38: 0 | G38: =F38 -> 0 | H38: 0 | I38: 0 | J38: 0 | K38: 0 | L38: 0 | M38: 0 | N38: 0 | O38: 0 | P38: 0 | Q38: 0
B39: Convertible senior notes, net | D39: $M | E39: 909847 | F39: 1697985 | G39: 1701397 | H39: 1701397 | I39: 1701397 | J39: 1701397 | K39: 1701397 | L39: 1701397 | M39: 1701397 | N39: 1701397 | O39: 1701397 | P39: 1701397 | Q39: 1701397
B40: Other long-term liabilities | D40: $M | E40: 34978 | F40: 20803 | G40: 28970 | H40: 28970 | I40: 28970 | J40: 28970 | K40: 28970 | L40: 28970 | M40: 28970 | N40: 28970 | O40: 28970 | P40: 28970 | Q40: 28970
B41: Total non-current liabilities | D41: $M | E41: =SUM(E36:E40) -> 1113924 | F41: =SUM(F36:F40) -> 1803675 | G41: =SUM(G36:G40) -> 1821181 | H41: =SUM(H36:H40) -> 1824158 | I41: =SUM(I36:I40) -> 1828521.5 | J41: =SUM(J36:J40) -> 1832075.4 | K41: =SUM(K36:K40) -> 1837709 | L41: =SUM(L36:L40) -> 1842697.4 | ... Q41: =SUM(Q36:Q40) -> 1881736.3
B43: Total liabilities | D43: $M | E43: =E41+E33 -> 3439583 | F43: =F41+F33 -> 5212332 | G43: =G41+G33 -> 5269569.9 | H43: =H41+H33 -> 6301824.8 | I43: =I41+I33 -> 7634843 | J43: =J41+J33 -> 9076235.5 | K43: =K41+K33 -> 10918457 | L43: =L41+L33 -> 13149527 | ... Q43: =Q41+Q33 -> 29941851
B46: Stockholders' equity:
B47: Preferred stock | D47: $M | E47: 0 | F47: 0 | G47: 0 | H47: 0 | I47: 0 | J47: 0 | K47: 0
B48: Common stock | D48: $M | E48: 2 | F48: 2 | G48: =F48 -> 2 | H48: 2 | I48: 2 | J48: 2 | K48: 2 | L48: 2 | M48: 2 | N48: 2 | O48: 2 | P48: 2 | Q48: 2
B49: Additional paid in capital | D49: $M | E49: 2777155 | F49: 4598737 | G49: =F49 -> 4598737 | H49: 4598737 | I49: 4598737 | J49: 4598737 | K49: 4598737 | L49: 4598737 | M49: 4598737 | N49: 4598737 | O49: 4598737 | P49: 4598737 | Q49: 4598737
...

Sheet Cash Flow Statement
E2: Historical | G2: Projection
B3: Cash Flow Statement | D3: Units | E3: FY 21 | F3: FY 22 | G3: FY 23 | H3: FY 24 | I3: FY 25 | J3: FY 26 | K3: FY 27 | L3: FY 28 | M3: FY 29 | N3: FY 30 | O3: FY 31 | P3: FY 32 | Q3: FY 33
B4: Cash flows from operating activities:
B6: (Net loss) gain | D6: $M | E6: -98720 | F6: -326361 | G6: ='Income Statement'!H32 -> -119507.11 | H6: ='Income Statement'!I32 -> -38904.215 | I6: ='Income Statement'!J32 -> 93954.793 | J6: ='Income Statement'!K32 -> 269621.92 | K6: ='Income Statement'!L32 -> 492798.38 | L6: ='Income Statement'!M32 -> 734959.02 | M6: ='Income Statement'!N32 -> 1058523.1 | N6: ='Income Statement'!O32 -> 1406816 | ... Q6: ='Income Statement'!R32 -> 2235007.4
B7: Adjustments to reconcile net loss to net cash (used in) provided by operating activities:
B8: Stock-based compensation | D8: $M | E8: 68290 | F8: 197157 | G8: 0 | H8: 0 | I8: 0 | J8: 0 | K8: 0 | L8: 0 | M8: 0 | N8: 0 | O8: 0 | P8: 0 | Q8: 0
B9: Amortization of intangible assets | D9: $M | E9: 5659 | F9: 75977 | G9: =Assumptions!I69 -> 79075 | H9: =Assumptions!J69 -> 78147 | I9: =Assumptions!K69 -> 59425 | J9: =Assumptions!L69 -> 57763 | K9: =Assumptions!M69 -> 55094 | L9: =Assumptions!N69 -> 45857 | M9: =Assumptions!O69 -> 15000 | N9: =Assumptions!P69 -> 10000 | ... Q9: =Assumptions!S69 -> 5000
B10: Depreciation and amortization | D10: $M | E10: 4443 | F10: 9161 | G10: =Assumptions!I54 -> 5364.463 | H10: =Assumptions!J54 -> 6988.7316 | I10: =Assumptions!K54 -> 9814.7127 | J10: =Assumptions!L54 -> 12116.412 | K10: =Assumptions!M54 -> 15764.964 | L10: =Assumptions!N54 -> 18995.66 | M10: =Assumptions!O54 -> 22913.218 | N10: =Assumptions!P54 -> 28575.579 | ... Q10: =Assumptions!S54 -> 44279.05
B11: Amortization of capitalized internal-use software costs | D11: $M | E11: 907 | F11: 2366 | G11: 0 | H11: 0 | I11: 0 | J11: 0 | K11: 0 | L11: 0 | M11: 0 | N11: 0 | O11: 0 | P11: 0 | Q11: 0
B12: Amortization of debt discount (accretion of debt premium) and issuance costs | D12: $M | E12: 27531 | F12: 4777 | G12: 0 | H12: 0 | I12: 0 | J12: 0 | K12: 0 | L12: 0 | M12: 0 | N12: 0 | O12: 0 | P12: 0 | Q12: 0
B13: Amortization of premium (accretion of discount) on investments in marketable debt securities | D13: $M | E13: 4692 | F13: 11386 | G13: 0 | H13: 0 | I13: 0 | J13: 0 | K13: 0 | L13: 0 | M13: 0 | N13: 0 | O13: 0 | P13: 0 | Q13: 0
B14: Provision for losses on acquired card receivables | D14: $M | E14: 741 | F14: 19879 | G14: =Assumptions!I87 -> 10121.855 | H14: =Assumptions!J87 -> 13265.615 | I14: =Assumptions!K87 -> 17281.054 | J14: =Assumptions!L87 -> 21836.34 | K14: =Assumptions!M87 -> 27506.201 | L14: =Assumptions!N87 -> 34609.319 | M14: =Assumptions!O87 -> 43557.205 | N14: =Assumptions!P87 -> 52172.82 | ... Q14: =Assumptions!S87 -> 87445.461
B15: Non-cash operating lease expense | D15: $M | E15: 3813 | F15: 8601 | G15: 0 | H15: 0 | I15: 0 | J15: 0 | K15: 0 | L15: 0 | M15: 0 | N15: 0 | O15: 0 | P15: 0 | Q15: 0
B16: Deferred income taxes | D16: $M | E16: -40617 | F16: -4075 | G16: 0 | H16: 0 | I16: 0 | J16: 0 | K16: 0 | L16: 0 | M16: 0 | N16: 0 | O16: 0 | P16: 0 | Q16: 0
B17: Other | D17: $M | E17: 0 | F17: -726 | G17: 0 | H17: 0 | I17: 0 | J17: 0 | K17: 0 | L17: 0 | M17: 0 | N17: 0 | O17: 0 | P17: 0 | Q17: 0
B19: Changes in assets and liabilities:
B20: Accounts receivable | D20: $M | E20: -6535 | F20: -3032 | G20: ='Balance Sheet'!F8-'Balance Sheet'!G8 -> -32864.8 | H20: ='Balance Sheet'!G8-'Balance Sheet'!H8 -> -21681.902 | I20: ='Balance Sheet'!H8-'Balance Sheet'!I8 -> -31779.538 | J20: ='Balance Sheet'!I8-'Balance Sheet'!J8 -> -25883.739 | K20: ='Balance Sheet'!J8-'Balance Sheet'!K8 -> -41029.74 | L20: ='Balance Sheet'!K8-'Balance Sheet'!L8 -> -36330.755 | M20: ='Balance Sheet'!L8-'Balance Sheet'!M8 -> -44054.861 | N20: ='Balance Sheet'!M8-'Balance Sheet'!N8 -> -63676.016 | ... Q20: ='Balance Sheet'!P8-'Balance Sheet'!Q8 -> -63767.117
B21: Prepaid expenses and other current assets | D21: $M | E21: 706 | F21: -12970 | G21: ='Balance Sheet'!F10-'Balance Sheet'!G10 -> 58176.455 | H21: ='Balance Sheet'!G10-'Balance Sheet'!H10 -> -28321.514 | I21: ='Balance Sheet'!H10-'Balance Sheet'!I10 -> -39061.792 | J21: ='Balance Sheet'!I10-'Balance Sheet'!J10 -> -25250.435 | K21: ='Balance Sheet'!J10-'Balance Sheet'!K10 -> -39814.211 | L21: ='Balance Sheet'!K10-'Balance Sheet'!L10 -> -26807.003 | M21: ='Balance Sheet'!L10-'Balance Sheet'!M10 -> -28626.856 | N21: ='Balance Sheet'!M10-'Balance Sheet'!N10 -> -69432.235 | ... Q21: ='Balance Sheet'!P10-'Balance Sheet'!Q10 -> -69531.571
B22: Other assets | D22: $M | E22: -12525 | F22: 5105 | G22: ='Balance Sheet'!F19-'Balance Sheet'!G19 -> -26397.79 | H22: ='Balance Sheet'!G19-'Balance Sheet'!H19 -> -22444.64 | I22: ='Balance Sheet'!H19-'Balance Sheet'!I19 -> -39050.27 | J22: ='Balance Sheet'!I19-'Balance Sheet'!J19 -> -31805.591 | K22: ='Balance Sheet'!J19-'Balance Sheet'!K19 -> -50416.794 | L22: ='Balance Sheet'!K19-'Balance Sheet'!L19 -> -44642.745 | M22: ='Balance Sheet'!L19-'Balance Sheet'!M19 -> -54134.022 | N22: ='Balance Sheet'!M19-'Balance Sheet'!N19 -> -78244.235 | ... Q22: ='Balance Sheet'!P19-'Balance Sheet'!Q19 -> -78356.179
B23: Accounts payable | D23: $M | E23: 7417 | F23: -3771 | G23: ='Balance Sheet'!G27-'Balance Sheet'!F27 -> 14991.968 | H23: ='Balance Sheet'!H27-'Balance Sheet'!G27 -> 5866.6103 | I23: ='Balance Sheet'!I27-'Balance Sheet'!H27 -> 7754.6523 | J23: ='Balance Sheet'!J27-'Balance Sheet'!I27 -> 4674.1674 | K23: ='Balance Sheet'!K27-'Balance Sheet'!J27 -> 11415.864 | L23: ='Balance Sheet'!L27-'Balance Sheet'!K27 -> 9210.7199 | M23: ='Balance Sheet'!M27-'Balance Sheet'!L27 -> 11978.819 | N23: ='Balance Sheet'!N27-'Balance Sheet'!M27 -> 17604.787 | ... Q23: ='Balance Sheet'!Q27-'Balance Sheet'!P27 -> 18283.928
B24: Accrued compensation | G24: ='Balance Sheet'!G28-'Balance Sheet'!F28 -> 82642.333 | H24: ='Balance Sheet'!H28-'Balance Sheet'!G28 -> 27193.402 | I24: ='Balance Sheet'!I28-'Balance Sheet'!H28 -> 38441.834 | J24: ='Balance Sheet'!J28-'Balance Sheet'!I28 -> 22835.531 | K24: ='Balance Sheet'!K28-'Balance Sheet'!J28 -> 40771.795 | L24: ='Balance Sheet'!L28-'Balance Sheet'!K28 -> 30340.222 | M24: ='Balance Sheet'!M28-'Balance Sheet'!L28 -> 31661.465 | N24: ='Balance Sheet'!N28-'Balance Sheet'!M28 -> 63090.528 | ... Q24: ='Balance Sheet'!Q28-'Balance Sheet'!P28 -> 70522.518
B25: Other accruals and current liabilities | D25: $M | E25: 22980 | F25: 7460 | G25: ='Balance Sheet'!G30-'Balance Sheet'!F30 -> 69647.269 | H25: ='Balance Sheet'!H30-'Balance Sheet'!G30 -> 46211.369 | I25: ='Balance Sheet'!I30-'Balance Sheet'!H30 -> 65326.499 | J25: ='Balance Sheet'!J30-'Balance Sheet'!I30 -> 38805.779 | K25: ='Balance Sheet'!K30-'Balance Sheet'!J30 -> 69285.941 | L25: ='Balance Sheet'!L30-'Balance Sheet'!K30 -> 51558.947 | M25: ='Balance Sheet'!M30-'Balance Sheet'!L30 -> 53804.215 | N25: ='Balance Sheet'!N30-'Balance Sheet'!M30 -> 107213.49 | ... Q25: ='Balance Sheet'!Q30-'Balance Sheet'!P30 -> 119843.12
B26: Operating lease liabilities | D26: $M | E26: 8395 | F26: -7877 | G26: ='Balance Sheet'!G37-'Balance Sheet'!F37 -> 272 | H26: ='Balance Sheet'!H37-'Balance Sheet'!G37 -> 0 | I26: ='Balance Sheet'!I37-'Balance Sheet'!H37 -> 0 | J26: ='Balance Sheet'!J37-'Balance Sheet'!I37 -> 0 | K26: ='Balance Sheet'!K37-'Balance Sheet'!J37 -> 0 | L26: ='Balance Sheet'!L37-'Balance Sheet'!K37 -> 0 | M26: ='Balance Sheet'!M37-'Balance Sheet'!L37 -> 0 | N26: ='Balance Sheet'!N37-'Balance Sheet'!M37 -> 0 | ... Q26: ='Balance Sheet'!Q37-'Balance Sheet'!P37 -> 0
B27: Other long-term liabilities | D27: $M | E27: 592 | F27: -6749 | G27: ='Balance Sheet'!G40-'Balance Sheet'!F40 -> 8167 | H27: ='Balance Sheet'!H40-'Balance Sheet'!G40 -> 0 | I27: ='Balance Sheet'!I40-'Balance Sheet'!H40 -> 0 | J27: ='Balance Sheet'!J40-'Balance Sheet'!I40 -> 0 | K27: ='Balance Sheet'!K40-'Balance Sheet'!J40 -> 0 | L27: ='Balance Sheet'!L40-'Balance Sheet'!K40 -> 0 | M27: ='Balance Sheet'!M40-'Balance Sheet'!L40 -> 0 | N27: ='Balance Sheet'!N40-'Balance Sheet'!M40 -> 0 | ... Q27: ='Balance Sheet'!Q40-'Balance Sheet'!P40 -> 0
B28: Deferred revenue | D28: $M | E28: 6854 | F28: 5599 | G28: =('Balance Sheet'!G29-'Balance Sheet'!F29)+('Balance Sheet'!G36-'Balance Sheet'!F36) -> 25517.665 | H28: =('Balance Sheet'!H29-'Balance Sheet'!G29)+('Balance Sheet'!H36-'Balance Sheet'!G36) -> 22685.751 | I28: =('Balance Sheet'!I29-'Balance Sheet'!H29)+('Balance Sheet'!I36-'Balance Sheet'!H36) -> 33250.897 | J28: =('Balance Sheet'!J29-'Balance Sheet'!I29)+('Balance Sheet'!J36-'Balance Sheet'!I36) -> 27082.129 | K28: =('Balance Sheet'!K29-'Balance Sheet'!J29)+('Balance Sheet'!K36-'Balance Sheet'!J36) -> 42929.375 | L28: =('Balance Sheet'!L29-'Balance Sheet'!K29)+('Balance Sheet'!L36-'Balance Sheet'!K36) -> 38012.832 | M28: =('Balance Sheet'!M29-'Balance Sheet'!L29)+('Balance Sheet'!M36-'Balance Sheet'!L36) -> 46094.555 | N28: =('Balance Sheet'!N29-'Balance Sheet'!M29)+('Balance Sheet'!N36-'Balance Sheet'!M36) -> 66624.15 | ... Q28: =('Balance Sheet'!Q29-'Balance Sheet'!P29)+('Balance Sheet'!Q36-'Balance Sheet'!P36) -> 66719.469
B30: Net cash (used in) provided by operating activities | D30: $M | E30: =SUM(E6:E28) -> 4623 | F30: =SUM(F6:F28) -> -18093 | G30: =SUM(G6:G28) -> 175206.31 | H30: =SUM(H6:H28) -> 89006.208 | I30: =SUM(I6:I28) -> 215357.84 | J30: =SUM(J6:J28) -> 371795.52 | K30: =SUM(K6:K28) -> 624305.77 | L30: =SUM(L6:L28) -> 855763.21 | ... Q30: =SUM(Q6:Q28) -> 2435446.1
B32: Cash flows from investing activities:
B34: Cash paid for acquisition, net of acquired cash and cash equivalents | D34: $M | E34: -556090 | F34: -144349 | G34: 0 | H34: 0 | I34: 0 | J34: 0 | K34: 0 | L34: 0 | M34: 0 | N34: 0 | O34: 0 | P34: 0 | Q34: 0
B35: Purchases of corporate and customer fund short-term investments | D35: $M | E35: -2070296 | F35: -2801697 | G35: ='Balance Sheet'!G7-'Balance Sheet'!F7 -> 0 | H35: ='Balance Sheet'!H7-'Balance Sheet'!G7 -> 0 | I35: ='Balance Sheet'!I7-'Balance Sheet'!H7 -> 0 | J35: ='Balance Sheet'!J7-'Balance Sheet'!I7 -> 0 | K35: ='Balance Sheet'!K7-'Balance Sheet'!J7 -> 0 | L35: ='Balance Sheet'!L7-'Balance Sheet'!K7 -> 0 | M35: ='Balance Sheet'!M7-'Balance Sheet'!L7 -> 0 | N35: ='Balance Sheet'!N7-'Balance Sheet'!M7 -> 0 | ... Q35: ='Balance Sheet'!Q7-'Balance Sheet'!P7 -> 0
B36: Proceeds from maturities of corporate and customer fund short-term investments | D36: $M | E36: 1104532 | F36: 1902474 | G36: 0 | H36: 0 | I36: 0 | J36: 0 | K36: 0 | L36: 0 | M36: 0 | N36: 0 | O36: 0 | P36: 0 | Q36: 0
B37: Proceeds from sale of corporate and customer fund short-term investments | D37: $M | E37: 142665 | F37: 55744 | G37: 0 | H37: 0 | I37: 0 | J37: 0 | K37: 0 | L37: 0 | M37: 0 | N37: 0 | O37: 0 | P37: 0 | Q37: 0
B38: Increase in acquired card receivables, net and other | D38: $M | E38: -26495 | F38: -130537 | G38: ='Balance Sheet'!F9-'Balance Sheet'!G9-G14 -> 11225.429 | H38: ='Balance Sheet'!G9-'Balance Sheet'!H9-H14 -> -86268.451 | I38: ='Balance Sheet'!H9-'Balance Sheet'!I9-I14 -> -110525.6 | J38: ='Balance Sheet'!I9-'Balance Sheet'!J9-J14 -> -127616.94 | K38: ='Balance Sheet'!J9-'Balance Sheet'!K9-K14 -> -159168.91 | L38: ='Balance Sheet'!K9-'Balance Sheet'!L9-L14 -> -199554.42 | M38: ='Balance Sheet'!L9-'Balance Sheet'!M9-M14 -> -251340.57 | N38: ='Balance Sheet'!M9-'Balance Sheet'!N9-N14 -> -252240.38 | ... Q38: ='Balance Sheet'!P9-'Balance Sheet'!Q9-Q14 -> -386601.08
B39: Purchases of property and equipment | D39: $M | E39: -18902 | F39: -5377 | G39: =-(Assumptions!I59) -> -9990 | H39: =-(Assumptions!J59) -> -13796.061 | I39: =-(Assumptions!K59) -> -19374.671 | J39: =-(Assumptions!L59) -> -23918.327 | K39: =-(Assumptions!M59) -> -31120.726 | L39: =-(Assumptions!N59) -> -37498.262 | M39: =-(Assumptions!O59) -> -45231.693 | N39: =-(Assumptions!P59) -> -56409.441 | ... Q39: =-(Assumptions!S59) -> -87408.778
B40: Capitalization of internal-use software costs | D40: $M | E40: -2304 | F40: -10259 | G40: 0 | H40: 0 | I40: 0 | J40: 0 | K40: 0 | L40: 0 | M40: 0 | N40: 0 | O40: 0 | P40: 0 | Q40: 0
B41: Proceeds from beneficial interest | D41: $M | E41: 0 | F41: 6699 | G41: 0 | H41: 0 | I41: 0 | J41: 0 | K41: 0 | L41: 0 | M41: 0 | N41: 0 | O41: 0 | P41: 0 | Q41: 0
B43: Net cash used in investing activities | D43: $M | E43: =SUM(E34:E41) -> -1426890 | F43: =SUM(F34:F41) -> -1127302 | G43: =SUM(G34:G41) -> 1235.429 | H43: =SUM(H34:H41) -> -100064.51 | I43: =SUM(I34:I41) -> -129900.28 | J43: =SUM(J34:J41) -> -151535.27 | K43: =SUM(K34:K41) -> -190289.64 | L43: =SUM(L34:L41) -> -237052.68 | ... Q43: =SUM(Q34:Q41) -> -474009.86
B45: Cash flows from financing activities:
B47: Proceeds from issuance of common stock upon public offering, net of underwriting discounts and other offering costs | D47: $M | E47: 0 | F47: 1341122 | G47: 0 | H47: 0 | I47: 0 | J47: 0 | K47: 0 | L47: 0 | M47: 0 | N47: 0 | O47: 0 | P47: 0 | Q47: 0
B48: Proceeds from issuance of convertible senior notes, net of discounts and issuance costs | D48: $M | E48: 1129379 | F48: 560075 | G48: ='Balance Sheet'!G39-'Balance Sheet'!F39 -> 3412 | H48: ='Balance Sheet'!H39-'Balance Sheet'!G39 -> 0 | I48: ='Balance Sheet'!I39-'Balance Sheet'!H39 -> 0 | J48: ='Balance Sheet'!J39-'Balance Sheet'!I39 -> 0 | K48: ='Balance Sheet'!K39-'Balance Sheet'!J39 -> 0 | L48: ='Balance Sheet'!L39-'Balance Sheet'!K39 -> 0 | M48: ='Balance Sheet'!M39-'Balance Sheet'!L39 -> 0 | N48: ='Balance Sheet'!N39-'Balance Sheet'!M39 -> 0 | ... Q48: ='Balance Sheet'!Q39-'Balance Sheet'!P39 -> 0
B49: Purchase of capped calls | D49: $M | E49: -87860 | F49: -37893 | G49: 0 | H49: 0 | I49: 0 | J49: 0 | K49: 0 | L49: 0 | M49: 0 | N49: 0 | O49: 0 | P49: 0 | Q49: 0
...

Sheet -------->

Sheet DCF
E2: Historical | G2: Projected
B3: Unlevered FCF | D3: Units | E3: FY 21 | F3: FY 22 | G3: FY 23 | H3: FY 24 | I3: FY 25 | J3: FY 26 | K3: FY 27 | L3: FY 28 | M3: FY 29 | N3: FY 30 | O3: FY 31 | P3: FY 32 | Q3: FY 33
B5: EBIT | D5: $ | G5: ='Income Statement'!H26 -> -151274.82 | H5: ='Income Statement'!I26 -> -49245.842 | I5: ='Income Statement'!J26 -> 118930.12 | J5: ='Income Statement'!K26 -> 341293.57 | K5: ='Income Statement'!L26 -> 623795.42 | L5: ='Income Statement'!M26 -> 930327.87 | M5: ='Income Statement'!N26 -> 1339902.6 | N5: ='Income Statement'!O26 -> 1780779.7 | ... Q5: ='Income Statement'!R26 -> 2829123.3
B6: % tax rate | D6: % | G6: 0.21 | H6: 0.21 | I6: 0.21 | J6: 0.21 | K6: 0.21 | L6: 0.21 | M6: 0.21 | N6: 0.21 | O6: 0.21 | P6: 0.21 | Q6: 0.21
B7: NOPAT | D7: $ | G7: =G5*(1-G6) -> -119507.11 | H7: =H5*(1-H6) -> -38904.215 | I7: =I5*(1-I6) -> 93954.793 | J7: =J5*(1-J6) -> 269621.92 | K7: =K5*(1-K6) -> 492798.38 | L7: =L5*(1-L6) -> 734959.02 | M7: =M5*(1-M6) -> 1058523.1 | N7: =N5*(1-N6) -> 1406816 | ... Q7: =Q5*(1-Q6) -> 2235007.4
B9: Adjustments for non-cash charges/reinvestment:
B10: (+) Depreciation and amortization | G10: =+'Cash Flow Statement'!G10+'Cash Flow Statement'!F9 -> 81341.463 | H10: =+'Cash Flow Statement'!H10+'Cash Flow Statement'!G9 -> 86063.732 | I10: =+'Cash Flow Statement'!I10+'Cash Flow Statement'!H9 -> 87961.713 | J10: =+'Cash Flow Statement'!J10+'Cash Flow Statement'!I9 -> 71541.412 | K10: =+'Cash Flow Statement'!K10+'Cash Flow Statement'!J9 -> 73527.964 | L10: =+'Cash Flow Statement'!L10+'Cash Flow Statement'!K9 -> 74089.66 | M10: =+'Cash Flow Statement'!M10+'Cash Flow Statement'!L9 -> 68770.218 | N10: =+'Cash Flow Statement'!N10+'Cash Flow Statement'!M9 -> 43575.579 | ... Q10: =+'Cash Flow Statement'!Q10+'Cash Flow Statement'!P9 -> 49279.05
B11: (-) Changes in NWC | G11: =('Balance Sheet'!G7+'Balance Sheet'!G8+'Balance Sheet'!G9+'Balance Sheet'!G10-'Balance Sheet'!G27-'Balance Sheet'!G28-'Balance Sheet'!G29-'Balance Sheet'!G30)-('Balance Sheet'!F7+'Balance Sheet'!F8+'Balance Sheet'!F9+'Balance Sheet'!F10-'Balance Sheet'!F27-'Balance Sheet'!F28-'Balance Sheet'!F29-'Balance Sheet'!F30) -> -233803.2 | H11: =('Balance Sheet'!H7+'Balance Sheet'!H8+'Balance Sheet'!H9+'Balance Sheet'!H10-'Balance Sheet'!H27-'Balance Sheet'!H28-'Balance Sheet'!H29-'Balance Sheet'!H30)-('Balance Sheet'!G7+'Balance Sheet'!G8+'Balance Sheet'!G9+'Balance Sheet'!G10-'Balance Sheet'!G27-'Balance Sheet'!G28-'Balance Sheet'!G29-'Balance Sheet'!G30) -> 24026.142 | I11: =('Balance Sheet'!I7+'Balance Sheet'!I8+'Balance Sheet'!I9+'Balance Sheet'!I10-'Balance Sheet'!I27-'Balance Sheet'!I28-'Balance Sheet'!I29-'Balance Sheet'!I30)-('Balance Sheet'!H7+'Balance Sheet'!H8+'Balance Sheet'!H9+'Balance Sheet'!H10-'Balance Sheet'!H27-'Balance Sheet'!H28-'Balance Sheet'!H29-'Balance Sheet'!H30) -> 23675.47 | J11: =('Balance Sheet'!J7+'Balance Sheet'!J8+'Balance Sheet'!J9+'Balance Sheet'!J10-'Balance Sheet'!J27-'Balance Sheet'!J28-'Balance Sheet'!J29-'Balance Sheet'!J30)-('Balance Sheet'!I7+'Balance Sheet'!I8+'Balance Sheet'!I9+'Balance Sheet'!I10-'Balance Sheet'!I27-'Balance Sheet'!I28-'Balance Sheet'!I29-'Balance Sheet'!I30) -> 67071.119 | K11: =('Balance Sheet'!K7+'Balance Sheet'!K8+'Balance Sheet'!K9+'Balance Sheet'!K10-'Balance Sheet'!K27-'Balance Sheet'!K28-'Balance Sheet'!K29-'Balance Sheet'!K30)-('Balance Sheet'!J7+'Balance Sheet'!J8+'Balance Sheet'!J9+'Balance Sheet'!J10-'Balance Sheet'!J27-'Balance Sheet'!J28-'Balance Sheet'!J29-'Balance Sheet'!J30) -> 53737.253 | L11: =('Balance Sheet'!L7+'Balance Sheet'!L8+'Balance Sheet'!L9+'Balance Sheet'!L10-'Balance Sheet'!L27-'Balance Sheet'!L28-'Balance Sheet'!L29-'Balance Sheet'!L30)-('Balance Sheet'!K7+'Balance Sheet'!K8+'Balance Sheet'!K9+'Balance Sheet'!K10-'Balance Sheet'!K27-'Balance Sheet'!K28-'Balance Sheet'!K29-'Balance Sheet'!K30) -> 103948.52 | M11: =('Balance Sheet'!M7+'Balance Sheet'!M8+'Balance Sheet'!M9+'Balance Sheet'!M10-'Balance Sheet'!M27-'Balance Sheet'!M28-'Balance Sheet'!M29-'Balance Sheet'!M30)-('Balance Sheet'!L7+'Balance Sheet'!L8+'Balance Sheet'!L9+'Balance Sheet'!L10-'Balance Sheet'!L27-'Balance Sheet'!L28-'Balance Sheet'!L29-'Balance Sheet'!L30) -> 142974.96 | N11: =('Balance Sheet'!N7+'Balance Sheet'!N8+'Balance Sheet'!N9+'Balance Sheet'!N10-'Balance Sheet'!N27-'Balance Sheet'!N28-'Balance Sheet'!N29-'Balance Sheet'!N30)-('Balance Sheet'!M7+'Balance Sheet'!M8+'Balance Sheet'!M9+'Balance Sheet'!M10-'Balance Sheet'!M27-'Balance Sheet'!M28-'Balance Sheet'!M29-'Balance Sheet'!M30) -> 87385.85 | ... Q11: =('Balance Sheet'!Q7+'Balance Sheet'!Q8+'Balance Sheet'!Q9+'Balance Sheet'!Q10-'Balance Sheet'!Q27-'Balance Sheet'!Q28-'Balance Sheet'!Q29-'Balance Sheet'!Q30)-('Balance Sheet'!P7+'Balance Sheet'!P8+'Balance Sheet'!P9+'Balance Sheet'!P10-'Balance Sheet'!P27-'Balance Sheet'!P28-'Balance Sheet'!P29-'Balance Sheet'!P30) -> 165840.79
B12: (-) Capital expenditures | G12: =-1*'Cash Flow Statement'!G39 -> 9990 | H12: =-1*'Cash Flow Statement'!H39 -> 13796.061 | I12: =-1*'Cash Flow Statement'!I39 -> 19374.671 | J12: =-1*'Cash Flow Statement'!J39 -> 23918.327 | K12: =-1*'Cash Flow Statement'!K39 -> 31120.726 | L12: =-1*'Cash Flow Statement'!L39 -> 37498.262 | M12: =-1*'Cash Flow Statement'!M39 -> 45231.693 | N12: =-1*'Cash Flow Statement'!N39 -> 56409.441 | ... Q12: =-1*'Cash Flow Statement'!Q39 -> 87408.778
B13: Unlevered Free Cash Flow | G13: =G7+G10-G11-G12 -> 185647.56 | H13: =H7+H10-H11-H12 -> 9337.3131 | I13: =I7+I10-I11-I12 -> 138866.36 | J13: =J7+J10-J11-J12 -> 250173.89 | K13: =K7+K10-K11-K12 -> 481468.36 | L13: =L7+L10-L11-L12 -> 667601.9 | M13: =M7+M10-M11-M12 -> 939086.66 | N13: =N7+N10-N11-N12 -> 1306596.2 | ... Q13: =Q7+Q10-Q11-Q12 -> 2031036.9
B15: Year | D15: # | G15: 1 | H15: 2 | I15: 3 | J15: 4 | K15: 5 | L15: 6 | M15: 7 | N15: 8 | O15: 9 | P15: 10 | Q15: 11
B16: Discount Factor | D16: # | G16: =(1+$F$51)^G15 -> 1.1144816 | H16: =(1+$F$51)^H15 -> 1.2420693 | I16: =(1+$F$51)^I15 -> 1.3842634 | J16: =(1+$F$51)^J15 -> 1.5427362 | K16: =(1+$F$51)^K15 -> 1.7193512 | L16: =(1+$F$51)^L15 -> 1.9161853 | M16: =(1+$F$51)^M15 -> 2.1355533 | N16: =(1+$F$51)^N15 -> 2.380035 | ... Q16: =(1+$F$51)^Q15 -> 3.2945954
B17: Near-term discounted free cash flow | D17: $ | G17: =G13/G16 -> 166577.49 | H17: =H13/H16 -> 7517.5458 | I17: =I13/I16 -> 100317.87 | J17: =J13/J16 -> 162162.46 | K17: =K13/K16 -> 280029.1 | L17: =L13/L16 -> 348401.54 | M17: =M13/M16 -> 439739.27 | N17: =N13/N16 -> 548981.95 | ... Q17: =Q13/Q16 -> 616475.36
B20: Beta Calculation
B21: Company | G21: Levered Beta | H21: Debt | I21: Equity | J21: D/E (%) | K21: Tax Rate (%) | L21: Unlevered Beta
B22: Paylocity | G22: 1.07 | H22: 100000 | I22: 8918000 | J22: =H22/I22 -> 0.011213277 | K22: 0.21 | L22: =G22/((1+(J22*(1-K22)))) -> 1.0606046
B23: Bentley Systems | G23: 1.22 | H23: =1430992+5000 -> 1435992 | I23: 11539000 | J23: =H23/I23 -> 0.12444683 | K23: 0.21 | L23: =G23/((1+(J23*(1-K23)))) -> 1.1107945
B24: ZoomInfo Technologies | G24: 0.91 | H24: 1235700 | I24: 11525000 | J24: =H24/I24 -> 0.10721909 | K24: 0.21 | L24: =G24/((1+(J24*(1-K24)))) -> 0.83893926
B25: Dynatrace | G25: 1.15 | H25: 273918 | I25: 12447000 | J25: =H25/I25 -> 0.022006749 | K25: 0.21 | L25: =G25/((1+(J25*(1-K25)))) -> 1.1303485
B26: Coupa Software Incorporated | G26: 1.15 | H26: 1615896 | I26: 6069000 | J26: =H26/I26 -> 0.26625408 | K26: 0.21 | L26: =G26/((1+(J26*(1-K26)))) -> 0.95014567
B27: Manhattan Associates | G27: 1.64 | H27: 0 | I27: 8918000 | J27: =H27/I27 -> 0 | K27: 0.21 | L27: =G27/((1+(J27*(1-K27)))) -> 1.64
B28: Average Unlevered Beta | L28: =AVERAGE(L22:L27) -> 1.1218054
D30: Debt | E30: Equity | F30: D/E | G30: Tax Rate | H30: Levered Beta
B31: Bill.com | D31: ='Balance Sheet'!F39+'Balance Sheet'!F31 -> 1773082 | E31: 9564000 | F31: =D31/E31 -> 0.18539126 | G31: 0.15 | H31: =L28*(1+(1-K27)*F31) -> 1.286104
B34: WACC Calculations | D34: Units
B35: Cost of Equity | H35: Cost of Debt
B36: Risk free rate | D36: % | F36: 0.0395 | H36: 0.0537
B37: Equity Risk Premium | D37: % | F37: 0.0594
B38: Beta | F38: =H31 -> 1.286104
B39: Cost of equity | F39: =F36+F38*F37 -> 0.11589458
B41: Current Stock Price | D41: $ | F41: 84.63
B42: Shares Outstanding | D42: Thousands | F42: 106385
B43: Market Cap in thousands | D43: $ | F43: =F41*F42 -> 9003362.5
B44: Net Debt thousands | D44: $ | F44: ='Balance Sheet'!F39+'Balance Sheet'!F31-'Balance Sheet'!F6 -> 176540
B46: E/(E+D) | D46: % | F46: =F43/(F43+F44) -> 0.98076886 | T46: WACC
B47: D/(E+D) | D47: % | F47: =F44/(F43+F44) -> 0.019231141 | O47: =F68 -> 99.119637 | P47: 0.105 | Q47: 0.1075 | R47: 0.11 | S47: 0.1125 | T47: 0.115 | U47: 0.1175 | V47: 0.12 | W47: 0.1225 | X47: 0.125
O48: 0.015 | P48: 107.01463 | Q48: 102.68487 | R48: 98.606809 | S48: 94.760601 | T48: 91.128386 | U48: 87.694065 | V48: 84.443076 | W48: 81.362227 | X48: 78.439532
B49: Tax Rate | D49: % | F49: 0.21 | O49: 0.0175 | P49: 109.24771 | Q49: 104.75004 | R49: 100.51967 | S49: 96.53499 | T49: 92.77664 | U49: 89.227192 | V49: 85.870931 | W49: 82.693651 | X49: 79.682475
O50: 0.02 | P50: 111.61215 | Q50: 106.93322 | R50: 102.53879 | S50: 98.405293 | T50: 94.511645 | U50: 90.838941 | V50: 87.370179 | W50: 84.090022 | X50: 80.984605
B51: WACC | D51: % | F51: =F39*F46+F47*H36*(1-F49) -> 0.11448164 | O51: 0.0225 | P51: 114.11988 | Q51: 109.24482 | R51: 104.6733 | S51: 100.3795 | T51: 96.340433 | U51: 92.535519 | V51: 88.946311 | W51: 85.556211 | X51: 82.350254
...
