Workbook

Sheet NWC Build
B2: (numbers in thousands) | E2: NWC Build
E3: Historical | J3: Projected
B4: Year | E4: 2019 | F4: 2020 | G4: 2021 | H4: 2022 | I4: 2023 | J4: 2024 | K4: 2025 | L4: 2026 | M4: 2027 | N4: 2028 | O4: 2029 | P4: 2030 | Q4: 2031 | R4: 2032 | S4: 2033
B5: Merchandise inventories | E5: 4676.848 | F5: 5247.477 | G5: 5614.325 | H5: 6760.733 | I5: 6994.266 | J5: ='DCF (Base Case)'!H4*J6 -> 7639.4127 | K5: ='DCF (Base Case)'!I4*K6 -> 7648.0581 | L5: ='DCF (Base Case)'!J4*L6 -> 7630.454 | M5: ='DCF (Base Case)'!K4*M6 -> 8126.5965 | N5: ='DCF (Base Case)'!L4*N6 -> 8589.7878 | O5: ='DCF (Base Case)'!M4*O6 -> 8583.6714 | P5: ='DCF (Base Case)'!N4*P6 -> 9020.5986 | Q5: ='DCF (Base Case)'!O4*Q6 -> 9436.2294 | ... S5: ='DCF (Base Case)'!Q4*S6 -> 9596.6104
B6: % of Revenue | E6: =E5/'DCF (Base Case)'!C4 -> 0.16851077 | F6: =F5/'DCF (Base Case)'!D4 -> 0.15549554 | G6: =G5/'DCF (Base Case)'!E4 -> 0.16406369 | H6: =H5/'DCF (Base Case)'!F4 -> 0.17864317 | I6: =I5/'DCF (Base Case)'!G$4 -> 0.18076962 | J6: 0.18 | K6: 0.17 | L6: 0.16 | M6: 0.16 | N6: 0.16 | O6: 0.15 | P6: 0.15 | Q6: 0.15 | R6: 0.14 | S6: 0.14
B7: Income taxes recievable | E7: 76.537 | F7: 90.76 | G7: 97.394 | H7: 135.775 | I7: 112.262 | J7: ='DCF (Base Case)'!H4*J8 -> 125.47599 | K7: ='DCF (Base Case)'!I4*K8 -> 134.79581 | L7: ='DCF (Base Case)'!J4*L8 -> 145.817 | M7: ='DCF (Base Case)'!K4*M8 -> 157.44668 | N7: ='DCF (Base Case)'!L4*N8 -> 161.18314 | O7: ='DCF (Base Case)'!M4*O8 -> 172.96064 | P7: ='DCF (Base Case)'!N4*P8 -> 182.55884 | Q7: ='DCF (Base Case)'!O4*Q8 -> 191.46705 | ... S7: ='DCF (Base Case)'!Q4*S8 -> 207.62825
B8: % of Revenue | E8: =E7/'DCF (Base Case)'!C$4 -> 0.0027576926 | F8: =F7/'DCF (Base Case)'!D$4 -> 0.0026894402 | G8: =G7/'DCF (Base Case)'!E$4 -> 0.0028460801 | H8: =H7/'DCF (Base Case)'!F$4 -> 0.0035876697 | I8: =I7/'DCF (Base Case)'!G$4 -> 0.0029014566 | J8: =AVERAGE(E8:I8) -> 0.0029564678 | K8: =AVERAGE(F8:J8) -> 0.0029962229 | L8: =AVERAGE(G8:K8) -> 0.0030575794 | M8: =AVERAGE(H8:L8) -> 0.0030998793 | N8: =AVERAGE(I8:M8) -> 0.0030023212 | O8: =AVERAGE(J8:N8) -> 0.0030224941 | P8: =AVERAGE(K8:O8) -> 0.0030356994 | Q8: =AVERAGE(L8:P8) -> 0.0030435947 | ... S8: =AVERAGE(N8:R8) -> 0.0030289814
B9: Prepaid expenses and other current assets | E9: 184.163 | F9: 199.405 | G9: 247.295 | H9: 302.925 | I9: 366.913 | J9: ='DCF (Base Case)'!H4*J10 -> 316.25757 | K9: ='DCF (Base Case)'!I4*K10 -> 342.58313 | L9: ='DCF (Base Case)'!J4*L10 -> 379.42902 | M9: ='DCF (Base Case)'!K4*M10 -> 411.51107 | N9: ='DCF (Base Case)'!L4*N10 -> 436.01422 | O9: ='DCF (Base Case)'!M4*O10 -> 449.16869 | P9: ='DCF (Base Case)'!N4*P10 -> 476.81414 | Q9: ='DCF (Base Case)'!O4*Q10 -> 502.73263 | ... S9: ='DCF (Base Case)'!Q4*S10 -> 546.86525
B10: % of Revenue | E10: =E9/'DCF (Base Case)'!C$4 -> 0.006635548 | F10: =F9/'DCF (Base Case)'!D$4 -> 0.0059088565 | G10: =G9/'DCF (Base Case)'!E$4 -> 0.0072265374 | H10: =H9/'DCF (Base Case)'!F$4 -> 0.008004381 | I10: =I9/'DCF (Base Case)'!G$4 -> 0.0094830144 | J10: =AVERAGE(E10:I10) -> 0.0074516675 | K10: =AVERAGE(F10:J10) -> 0.0076148914 | L10: =AVERAGE(G10:K10) -> 0.0079560983 | M10: =AVERAGE(H10:L10) -> 0.0081020105 | N10: =AVERAGE(I10:M10) -> 0.0081215364 | O10: =AVERAGE(J10:N10) -> 0.0078492408 | P10: =AVERAGE(K10:O10) -> 0.0079287555 | Q10: =AVERAGE(L10:P10) -> 0.0079915283 | ... S10: =AVERAGE(N10:R10) -> 0.0079779351
B11: Operating Lease Liabilities | E11: 964.805 | F11: 1074.079 | G11: 1183.559 | H11: 1288.939 | I11: 1387.083 | J11: ='DCF (Base Case)'!H4*J12 -> 2334.265 | K11: ='DCF (Base Case)'!I4*K12 -> 2474.3717 | L11: ='DCF (Base Case)'!J4*L12 -> 1907.6135 | M11: ='DCF (Base Case)'!K4*M12 -> 1930.0667 | N11: ='DCF (Base Case)'!L4*N12 -> 2040.0746 | O11: ='DCF (Base Case)'!M4*O12 -> 2060.0811 | P11: ='DCF (Base Case)'!N4*P12 -> 2044.669 | Q11: ='DCF (Base Case)'!O4*Q12 -> 1950.1541 | ... S11: ='DCF (Base Case)'!Q4*S12 -> 1439.4916
B12: % of Revenue | E12: =E11/'DCF (Base Case)'!C$4 -> 0.034762737 | F12: =F11/'DCF (Base Case)'!D$4 -> 0.031827581 | G12: =G11/'DCF (Base Case)'!E$4 -> 0.034586358 | H12: =H11/'DCF (Base Case)'!F$4 -> 0.03405846 | I12: =I11/'DCF (Base Case)'!G$4 -> 0.035849719 | J12: 0.055 | K12: 0.055 | L12: 0.04 | M12: 0.038 | N12: 0.038 | O12: 0.036 | P12: 0.034 | Q12: 0.031 | R12: 0.024 | S12: 0.021
B13: Accounts Payable | E13: 2860.682 | F13: 3614.089 | G13: 3738.604 | H13: 3552.991 | I13: 3587.374 | J13: ='DCF (Base Case)'!H4*J14 -> 4295.1993 | K13: ='DCF (Base Case)'!I4*K14 -> 4536.1863 | L13: ='DCF (Base Case)'!J4*L14 -> 4748.8524 | M13: ='DCF (Base Case)'!K4*M14 -> 4959.3593 | N13: ='DCF (Base Case)'!L4*N14 -> 5282.3899 | O13: ='DCF (Base Case)'!M4*O14 -> 5638.2823 | P13: ='DCF (Base Case)'!N4*P14 -> 5953.2544 | Q13: ='DCF (Base Case)'!O4*Q14 -> 6204.4627 | ... S13: ='DCF (Base Case)'!Q4*S14 -> 6758.5088
B14: % of Revenue | E14: =E13/'DCF (Base Case)'!C$4 -> 0.10307278 | F14: =F13/'DCF (Base Case)'!D$4 -> 0.10709427 | G14: =G13/'DCF (Base Case)'!E$4 -> 0.10925074 | H14: =H13/'DCF (Base Case)'!F$4 -> 0.093882954 | I14: =I13/'DCF (Base Case)'!G$4 -> 0.092717127 | J14: =AVERAGE(E14:I14) -> 0.10120358 | K14: =AVERAGE(F14:J14) -> 0.10082973 | L14: =AVERAGE(G14:K14) -> 0.099576826 | M14: =AVERAGE(H14:L14) -> 0.097642043 | N14: =AVERAGE(I14:M14) -> 0.098393861 | O14: =AVERAGE(J14:N14)-0.001 -> 0.098529208 | P14: =AVERAGE(K14:O14) -> 0.098994334 | Q14: =AVERAGE(L14:P14) -> 0.098627254 | R14: =AVERAGE(M14:Q14) -> 0.09843734 | S14: =AVERAGE(N14:R14) -> 0.098596399 | U14: NOTES 4/29
B15: Accrued expenses | E15: 709.156 | F15: 1006.552 | G15: 1049.139 | H15: 1036.919 | I15: 971.89 | J15: ='DCF (Base Case)'!H4*J16 -> 1176.0828 | K15: ='DCF (Base Case)'!I4*K16 -> 1266.103 | L15: ='DCF (Base Case)'!J4*L16 -> 1326.0776 | M15: ='DCF (Base Case)'!K4*M16 -> 1383.3267 | N15: ='DCF (Base Case)'!L4*N16 -> 1460.4152 | O15: ='DCF (Base Case)'!M4*O16 -> 1580.5173 | P15: ='DCF (Base Case)'!N4*P16 -> 1659.8711 | Q15: ='DCF (Base Case)'!O4*Q16 -> 1729.539 | ... S15: ='DCF (Base Case)'!Q4*S16 -> 1882.9551 | U15: - project in terms of days
B16: % of Revenue | E16: =E15/'DCF (Base Case)'!C$4 -> 0.025551488 | F16: =F15/'DCF (Base Case)'!D$4 -> 0.029826591 | G16: =G15/'DCF (Base Case)'!E$4 -> 0.030658292 | H16: =H15/'DCF (Base Case)'!F$4 -> 0.027399174 | I16: =I15/'DCF (Base Case)'!G$4 -> 0.025118889 | J16: =AVERAGE(E16:I16) -> 0.027710887 | K16: =AVERAGE(F16:J16) -> 0.028142766 | L16: =AVERAGE(G16:K16) -> 0.027806001 | M16: =AVERAGE(H16:L16) -> 0.027235543 | N16: =AVERAGE(I16:M16) -> 0.027202817 | O16: =AVERAGE(J16:N16) -> 0.027619603 | P16: =AVERAGE(K16:O16) -> 0.027601346 | Q16: =AVERAGE(L16:P16) -> 0.027493062 | ... S16: =AVERAGE(N16:R16) -> 0.027469461 | U16: - divide inventory balance by COGS
B17: Income Taxes Payable | E17: 8.362 | F17: 16.063 | G17: 8.055 | H17: 8.919 | I17: 10.709 | J17: ='DCF (Base Case)'!$H4*J18 -> 12.945516 | K17: ='DCF (Base Case)'!I4*K18 -> 13.756114 | L17: ='DCF (Base Case)'!J4*L18 -> 12.958689 | M17: ='DCF (Base Case)'!K4*M18 -> 14.170428 | N17: ='DCF (Base Case)'!L4*N18 -> 15.443249 | O17: ='DCF (Base Case)'!M4*O18 -> 16.585583 | P17: ='DCF (Base Case)'!N4*P18 -> 17.247143 | Q17: ='DCF (Base Case)'!O4*Q18 -> 17.803106 | R17: ='DCF (Base Case)'!P4*R18 -> 18.847064 | S17: ='DCF (Base Case)'!Q4*S18 -> 19.639401
B18: % of Revenue | E18: =E17/'DCF (Base Case)'!C$4 -> 0.0003012899 | F18: =F17/'DCF (Base Case)'!D$4 -> 0.00047598587 | G18: =G17/'DCF (Base Case)'!E$4 -> 0.00023538591 | H18: =H17/'DCF (Base Case)'!F$4 -> 0.00023567244 | I18: =I17/'DCF (Base Case)'!G$4 -> 0.00027677842 | J18: =AVERAGE(E18:I18) -> 0.00030502251 | K18: =AVERAGE(F18:J18) -> 0.00030576903 | L18: =AVERAGE(G18:K18) -> 0.00027172566 | M18: =AVERAGE(H18:L18) -> 0.00027899361 | N18: =AVERAGE(I18:M18) -> 0.00028765785 | O18: =AVERAGE(J18:N18) -> 0.00028983373 | P18: =AVERAGE(K18:O18) -> 0.00028679598 | Q18: =AVERAGE(L18:P18) -> 0.00028300137 | ... S18: =AVERAGE(N18:R18) -> 0.00028650909
B20: Net Working Capital | E20: =E5+E7+E9-E11-E13-E15-E17 -> 394.543 | F20: =F5+F7+F9-F11-F13-F15-F17 -> -173.141 | G20: =G5+G7+G9-G11-G13-G15-G17 -> -20.343 | H20: =H5+H7+H9-H11-H13-H15-H17 -> 1311.665 | I20: =I5+I7+I9-I11-I13-I15-I17 -> 1516.385 | J20: =J5+J7+J9-J11-J13-J15-J17 -> 262.65366 | K20: =K5+K7+K9-K11-K13-K15-K17 -> -164.98008 | L20: =L5+L7+L9-L11-L13-L15-L17 -> 160.1978 | ... S20: =S5+S7+S9-S11-S13-S15-S17 -> 250.50904
B21: Change in NWC | E21: - | F21: =F20-E20 -> -567.684 | G21: =G20-F20 -> 152.798 | H21: =H20-G20 -> 1332.008 | I21: =I20-H20 -> 204.72 | J21: =J20-I20 -> -1253.7313 | K21: =K20-J20 -> -427.63374 | L21: =L20-K20 -> 325.17787 | M21: =M20-L20 -> 248.43336 | ... S21: =S20-R20 -> 191.94798
O23: **Assumptions
O24: Inventory: This was really the only NWC item I could find discussed in any transcripts. However there is a consistent and clear message from the managetment team about their desire to reduce inventory . This is included elsewhere in our model as well.
O27: Operating Lease Liability: This was not touched on directly, but given our assumptions for an increase in CapEX as a % of revenue in the first 2 years I think that operating lease liability should follow suit

Sheet Revenue Build (Base Case)
E2: Revenue Model
E3: Historical | J3: Projected
B4: Year | E4: 2019 | F4: 2020 | G4: 2021 | H4: 2022 | I4: 2023 | J4: 2024 | K4: 2025 | L4: 2026 | M4: 2027 | N4: 2028 | O4: =N4+1 -> 2029 | P4: =O4+1 -> 2030 | Q4: =P4+1 -> 2031 | R4: =Q4+1 -> 2032 | S4: =R4+1 -> 2033
B5: # of New and Acquired Stores (U.S.) | E5: 975 | F5: 1000 | G5: 1050 | H5: 1039 | I5: 744 | J5: 700 | K5: 720 | L5: 750 | M5: 750 | N5: 750 | O5: 780 | P5: 780 | Q5: 800 | R5: 800 | S5: 800 | U5: BASE CASE
B6: # of New And Acquired Stores (Mexico) | E6: 0 | F6: 0 | G6: 0 | H6: 0 | I6: 3 | J6: 15 | K6: 20 | L6: 20 | M6: 20 | N6: 20 | O6: 25 | P6: 25 | Q6: 25 | R6: 30 | S6: 30 | U6: Assumptions:
B7: # of New PopShelf Stores | I7: 240 | J7: 250 | K7: 250 | L7: 250 | M7: 280 | N7: 280 | O7: 300 | P7: 300 | Q7: 300 | R7: 320 | S7: 320 | U7: - Between 700-800 new DG stores to be built per year
B8: # of New and Acquired Stores (Total) | E8: =E5+E6 -> 975 | F8: =F5+F6 -> 1000 | G8: =G5+G6 -> 1050 | H8: =H5+H6 -> 1039 | I8: =I5+I6+I7 -> 987 | J8: =J5+J6+J7 -> 965 | K8: =K5+K6+K7 -> 990 | L8: =L5+L6+L7 -> 1020 | M8: =M5+M6+M7 -> 1050 | N8: =N5+N6+N7 -> 1050 | O8: =O5+O6+O7 -> 1105 | P8: =P5+P6+P7 -> 1105 | ... S8: =S5+S6+S7 -> 1150 | U8: over projected period; roughly in alignment with CEO Vasos'
B9: # of Closed Stores | E9: 67 | F9: 101 | G9: 97 | H9: 65 | I9: 105 | J9: =AVERAGE($F9:$I9) -> 92 | K9: 95 | L9: 100 | M9: 85 | N9: 85 | O9: 82 | P9: 82 | Q9: 78 | R9: 75 | S9: 75 | U9: visions; PopShelf store numbers reflect earnings call quotes and
U10: general optimistic sentiment surrounding performance of the brand
B11: # of Beginning Stores | E11: =15370 -> 15370 | F11: =E15 -> 16278 | G11: =F15 -> 17177 | H11: =G15 -> 18130 | I11: =H15 -> 19104 | J11: =I15 -> 19986 | K11: =J15 -> 20859 | L11: =K15 -> 21754 | M11: =L15 -> 22674 | ... S11: =R15 -> 28772 | U11: - store closures to remain an average of historical five-year period numbers;
B12: # of New and Acquired Stores | E12: =E8 -> 975 | F12: =F8 -> 1000 | G12: =G8 -> 1050 | H12: =H8 -> 1039 | I12: =I8 -> 987 | J12: =J8 -> 965 | K12: =K8 -> 990 | L12: =L8 -> 1020 | ... S12: =S8 -> 1150 | U12: predict consistency with store closures following risks like poor sales performance
B13: # of Closed Stores | E13: =E9 -> 67 | F13: =F9 -> 101 | G13: =G9 -> 97 | H13: =H9 -> 65 | I13: =I9 -> 105 | J13: =J9 -> 92 | K13: =K9 -> 95 | L13: =L9 -> 100 | ... S13: =S9 -> 75 | U13: in select locations and higher-than-expected operating costs
B14: Closed Stores Proportion | E14: =E13/E11 -> 0.0043591412 | F14: =F13/F11 -> 0.0062046935 | G14: =G13/G11 -> 0.0056470862 | H14: =H13/H11 -> 0.0035852179 | I14: =I13/I11 -> 0.0054962312 | J14: =J13/J11 -> 0.0046032223 | K14: =K13/K11 -> 0.004554389 | L14: =L13/L11 -> 0.0045968558 | ... S14: =S13/S11 -> 0.002606701 | U14: - Average sales per square foot to remain steady over projected period; increased
B15: # of Ending Stores | E15: =E11+E12-E13 -> 16278 | F15: =F11+F12-F13 -> 17177 | G15: =G11+G12-G13 -> 18130 | H15: =H11+H12-H13 -> 19104 | I15: =I11+I12-I13 -> 19986 | J15: =J11+J12-J13 -> 20859 | K15: =K11+K12-K13 -> 21754 | L15: =L11+L12-L13 -> 22674 | ... S15: =S11+S12-S13 -> 29847 | U15: store sizes (bringing down these numbers) is offset by improved inventory distribution
B16: Growth Rate in # of Stores | E16: - | F16: =(F15-E15)/E15 -> 0.055227915 | G16: =(G15-F15)/F15 -> 0.055481167 | H16: =(H15-G15)/G15 -> 0.053723111 | I16: =(I15-H15)/H15 -> 0.046168342 | J16: =(J15-I15)/I15 -> 0.043680576 | K16: =(K15-J15)/J15 -> 0.042907138 | L16: =(L15-K15)/K15 -> 0.042291073 | M16: =(M15-L15)/L15 -> 0.04255976 | ... S16: =(S15-R15)/R15 -> 0.037362714 | U16: and reduction of shrink --> consistent projected numbers
B17: Selling Square Footage (in thousands) | E17: 120342 | F17: 127056 | G17: 134532 | H17: 142987 | I17: 151095 | J17: =ROUND(I17*(1+J18), 0) -> 160161 | K17: =ROUND(J17*(1+K18), 0) -> 169771 | L17: =ROUND(K17*(1+L18), 0) -> 179957 | M17: =ROUND(L17*(1+M18), 0) -> 191654 | N17: =ROUND(M17*(1+N18), 0) -> 202578 | O17: =ROUND(N17*(1+O18), 0) -> 213517 | P17: =ROUND(O17*(1+P18), 0) -> 224406 | Q17: =ROUND(P17*(1+Q18), 0) -> 234729 | ... S17: =ROUND(R17*(1+S18), 0) -> 253881
B18: Growth Rate of Selling Square Footage | E18: - | F18: 0.056 | G18: 0.059 | H18: 0.063 | I18: 0.057 | J18: 0.06 | K18: 0.06 | L18: 0.06 | M18: 0.065 | N18: 0.057 | O18: 0.054 | P18: 0.051 | Q18: 0.046 | R18: 0.0425 | S18: 0.0375
B19: Average Square Foot per Store | E19: =ROUND((E17/E15)*1000, 0) -> 7393 | F19: =ROUND((F17/F15)*1000, 0) -> 7397 | G19: =ROUND((G17/G15)*1000, 0) -> 7420 | H19: =ROUND((H17/H15)*1000, 0) -> 7485 | I19: =ROUND((I17/I15)*1000, 0) -> 7560 | J19: =ROUND((J17/J15)*1000, 0) -> 7678 | K19: =ROUND((K17/K15)*1000, 0) -> 7804 | L19: =ROUND((L17/L15)*1000, 0) -> 7937 | ... S19: =ROUND((S17/S15)*1000, 0) -> 8506 | U19: - aligns with target of store to expand store sizes to
B20: Growth Rate of Average Square Foot per Store | E20: - | F20: =(F19-E19)/E19 -> 0.00054105235 | G20: =(G19-F19)/F19 -> 0.0031093687 | H20: =(H19-G19)/G19 -> 0.0087601078 | I20: =(I19-H19)/H19 -> 0.01002004 | J20: =(J19-I19)/I19 -> 0.015608466 | K20: =(K19-J19)/J19 -> 0.016410524 | L20: =(L19-K19)/K19 -> 0.017042542 | M20: =(M19-L19)/L19 -> 0.021544664 | ... S20: =(S19-R19)/R19 -> 0.0001175779 | U20: include more 8500 sq ft. store formats
B21: Average Sales per Square Foot | E21: 237 | F21: 273 | G21: 262 | H21: 273 | I21: 264 | J21: 265 | K21: 265 | L21: 265 | M21: 265 | N21: 265 | O21: 268 | P21: 268 | Q21: 268 | R21: 270 | S21: 270
B22: Growth Rate of Average Sales per Square Foot | E22: - | F22: =(F21-E21)/E21 -> 0.15189873 | G22: =(G21-F21)/F21 -> -0.04029304 | H22: =(H21-G21)/G21 -> 0.041984733 | I22: =(I21-H21)/H21 -> -0.032967033 | J22: =(J21-I21)/I21 -> 0.0037878788 | K22: =(K21-J21)/J21 -> 0 | L22: =(L21-K21)/K21 -> 0 | M22: =(M21-L21)/L21 -> 0 | ... S22: =(S21-R21)/R21 -> 0
B23: Revenue Projections | J23: =J19*J15*J21 -> 42441181530 | K23: =K19*K15*K21 -> 44988577240 | L23: =L19*L15*L21 -> 47690337570 | M23: =M19*M15*M21 -> 50791228180 | N23: =N19*N15*N21 -> 53686174040 | O23: =O19*O15*O21 -> 57224475952 | P23: =P19*P15*P21 -> 60137324000 | Q23: =Q19*Q15*Q21 -> 62908196100 | ... S23: =S19*S15*S21 -> 68547217140
B28: Total Revenue | E28: 27754 | F28: 33746.8 | G28: 34220.4 | H28: 37844.9 | I28: 38691.6 | J28: =J23/1000000 -> 42441.182 | K28: =K23/1000000 -> 44988.577 | L28: =L23/1000000 -> 47690.338 | M28: =M23/1000000 -> 50791.228 | N28: =N23/1000000 -> 53686.174 | O28: =O23/1000000 -> 57224.476 | P28: =P23/1000000 -> 60137.324 | Q28: =Q23/1000000 -> 62908.196 | ... S28: =S23/1000000 -> 68547.217
B29: Growth Rate of Total Revenue | E29: - | F29: =(F28-E28)/E28 -> 0.21592563 | G29: =(G28-F28)/F28 -> 0.014033923 | H29: =(H28-G28)/G28 -> 0.10591635 | I29: =(I28-H28)/H28 -> 0.022372896 | J29: =(J28-I28)/I28 -> 0.096909446 | K29: =(K28-J28)/J28 -> 0.060021791 | L29: =(L28-K28)/K28 -> 0.060054363 | M29: =(M28-L28)/L28 -> 0.06502136 | ... S29: =(S28-R28)/R28 -> 0.037484685
B30: COGS + Operating Costs | E30: =(1-0.32)*E28 -> 18872.72 | F30: =(1-0.32)*F28 -> 22947.824 | G30: =(1-0.32)*G28 -> 23269.872 | H30: =(1-0.32)*H28 -> 25734.532 | I30: =(1-0.32)*I28 -> 26310.288 | J30: =(1-0.32)*J28 -> 28860.003 | K30: =(1-0.32)*K28 -> 30592.233 | L30: =(1-0.32)*L28 -> 32429.43 | ... S30: =(1-0.32)*S28 -> 46612.108
B31: Total Store Sales by Segment
B32: % Sales of Consumables | E32: 0.78 | F32: 0.768 | G32: 0.767 | H32: 0.797 | I32: 0.81 | J32: 0.81 | K32: 0.81 | L32: 0.815 | M32: 0.815 | N32: 0.82
B33: Growth Rate of Consumables Sales | E33: - | F33: =(F32-E32)/E32 -> -0.015384615 | G33: =(G32-F32)/F32 -> -0.0013020833 | H33: =(H32-G32)/G32 -> 0.039113429 | I33: =(I32-H32)/H32 -> 0.016311167 | J33: =(J32-I32)/I32 -> 0 | K33: =(K32-J32)/J32 -> 0 | L33: =(L32-K32)/K32 -> 0.0061728395 | M33: =(M32-L32)/L32 -> 0 | N33: =(N32-M32)/M32 -> 0.0061349693
B34: % Sales of Seasonal | E34: 0.117 | F34: 0.121 | G34: 0.122 | H34: 0.11 | I34: 0.106 | J34: 0.105 | K34: 0.105 | L34: 0.1 | M34: 0.1 | N34: 0.095
B35: Growth Rate of Seasonal Sales | E35: - | F35: =(F34-E34)/E34 -> 0.034188034 | G35: =(G34-F34)/F34 -> 0.0082644628 | H35: =(H34-G34)/G34 -> -0.098360656 | I35: =(I34-H34)/H34 -> -0.036363636 | J35: =(J34-I34)/I34 -> -0.0094339623 | K35: =(K34-J34)/J34 -> 0 | L35: =(L34-K34)/K34 -> -0.047619048 | M35: =(M34-L34)/L34 -> 0 | N35: =(N34-M34)/M34 -> -0.05
B36: % Sales of Home Products | E36: 0.058 | F36: 0.065 | G36: 0.068 | H36: 0.062 | I36: 0.056 | J36: 0.055 | K36: 0.055 | L36: 0.053 | M36: 0.051 | N36: 0.051
B37: Growth Rate of Home Products Sales | E37: - | F37: =(F36-E36)/E36 -> 0.12068966 | G37: =(G36-F36)/F36 -> 0.046153846 | H37: =(H36-G36)/G36 -> -0.088235294 | I37: =(I36-H36)/H36 -> -0.096774194 | J37: =(J36-I36)/I36 -> -0.017857143 | K37: =(K36-J36)/J36 -> 0 | L37: =(L36-K36)/K36 -> -0.036363636 | M37: =(M36-L36)/L36 -> -0.037735849 | N37: =(N36-M36)/M36 -> 0
B38: % Sales of Apparel | E38: 0.045 | F38: 0.046 | G38: 0.043 | H38: 0.031 | I38: 0.028 | J38: =1-J36-J34-J32 -> 0.03 | K38: =1-K36-K34-K32 -> 0.03 | L38: =1-L36-L34-L32 -> 0.032 | M38: =1-M36-M34-M32 -> 0.034 | N38: =1-N36-N34-N32 -> 0.034
B39: Growth Rate of Apparel Sales | E39: - | F39: =(F38-E38)/E38 -> 0.022222222 | G39: =(G38-F38)/F38 -> -0.065217391 | H39: =(H38-G38)/G38 -> -0.27906977 | I39: =(I38-H38)/H38 -> -0.096774194 | J39: =(J38-I38)/I38 -> 0.071428571 | K39: =(K38-J38)/J38 -> 0 | L39: =(L38-K38)/K38 -> 0.066666667 | M39: =(M38-L38)/L38 -> 0.0625 | N39: =(N38-M38)/M38 -> 0

Sheet DCF (Base Case)
B2: All numbers in millions of dollars. | C2: Historical | H2: Projected
B3: Year | C3: 2019 | D3: 2020 | E3: 2021 | F3: 2022 | G3: 2023 | H3: 2024 | I3: 2025 | J3: 2026 | K3: 2027 | L3: 2028 | M3: 2029 | N3: 2030 | O3: 2031 | P3: 2032 | Q3: 2033
B4: Revenue | C4: ='Revenue Build (Base Case)'!E28 -> 27754 | D4: ='Revenue Build (Base Case)'!F28 -> 33746.8 | E4: ='Revenue Build (Base Case)'!G28 -> 34220.4 | F4: ='Revenue Build (Base Case)'!H28 -> 37844.9 | G4: ='Revenue Build (Base Case)'!I28 -> 38691.6 | H4: ='Revenue Build (Base Case)'!J28 -> 42441.182 | I4: ='Revenue Build (Base Case)'!K28 -> 44988.577 | J4: ='Revenue Build (Base Case)'!L28 -> 47690.338 | ... Q4: ='Revenue Build (Base Case)'!S28 -> 68547.217
B5: revenue growth | C5: 0.083 | D5: 0.216 | E5: 0.014 | F5: 0.106 | G5: 0.022 | H5: =(H4-G4)/G4 -> 0.096909446 | I5: =(I4-H4)/H4 -> 0.060021791 | J5: =(J4-I4)/I4 -> 0.060054363 | K5: =(K4-J4)/J4 -> 0.06502136 | L5: =(L4-K4)/K4 -> 0.056996965 | M5: =(M4-L4)/L4 -> 0.065907135 | N5: =(N4-M4)/M4 -> 0.050902136 | O5: =(O4-N4)/N4 -> 0.046075747 | ... Q5: =(Q4-P4)/P4 -> 0.037484685
B6: EBIT | C6: 2336.9 | D6: 3557.5 | E6: 3223.3 | F6: 3330.4 | G6: 2453 | H6: =H7*H4 -> 2835.0709 | I6: =I7*I4 -> 3230.1798 | J6: =J7*J4 -> 3567.2373 | K6: =K7*K4 -> 3799.1839 | L6: =L7*L4 -> 4123.0982 | M6: =M7*M4 -> 4566.5132 | N6: =N7*N4 -> 4798.9585 | O6: =O7*O4 -> 5020.074 | ... Q6: =Q7*Q4 -> 5470.0679
B7: %rev | C7: 0.084 | D7: 0.105 | E7: 0.094 | F7: 0.088 | G7: 0.063 | H7: =AVERAGE($C$7:$G$7)-0.02 -> 0.0668 | I7: =AVERAGE($C$7:$G$7)-0.015 -> 0.0718 | J7: =AVERAGE($C$7:$G$7)-0.012 -> 0.0748 | K7: =AVERAGE($C$7:$G$7)-0.012 -> 0.0748 | L7: =AVERAGE($C$7:$G$7)-0.01 -> 0.0768 | M7: =AVERAGE($C$7:$G$7)-0.007 -> 0.0798 | N7: =AVERAGE($C$7:$G$7)-0.007 -> 0.0798 | O7: =AVERAGE($C$7:$G$7)-0.007 -> 0.0798 | P7: =AVERAGE($C$7:$G$7)-0.008 -> 0.0788 | Q7: =AVERAGE($C$7:$G$7)-0.007 -> 0.0798
B8: NOPAT | C8: =C6*(1-$C26) -> 1832.1296 | D8: =D6*(1-$C26) -> 2789.08 | E8: =E6*(1-$C26) -> 2527.0672 | F8: =F6*(1-$C26) -> 2611.0336 | G8: =G6*(1-$C26) -> 1923.152 | H8: =H6*(1-$C26) -> 2222.6956 | I8: =I6*(1-$C26) -> 2532.461 | J8: =J6*(1-$C26) -> 2796.714 | ... Q8: =Q6*(1-$C26) -> 4288.5333
B9: %rev | C9: =C8/C4 -> 0.066013173 | D9: =D8/D4 -> 0.082647244 | E9: =E8/E4 -> 0.073846805 | F9: =F8/F4 -> 0.068993011 | G9: =G8/G4 -> 0.049704639 | H9: =H8/H4 -> 0.0523712 | I9: =I8/I4 -> 0.0562912 | J9: =J8/J4 -> 0.0586432 | ... Q9: =Q8/Q4 -> 0.0625632
B10: (+) D&A | C10: 504.8 | D10: 574.2 | E10: 641.3 | F10: 724.9 | G10: 848.8 | H10: =H11*H4 -> 2079.9207 | I10: =I11*I4 -> 2204.7613 | J10: =J11*J4 -> 2098.7151 | K10: =K11*K4 -> 2235.1764 | L10: =L11*L4 -> 2094.1438 | M10: =M11*M4 -> 2060.4894 | N10: =N11*N4 -> 1744.4115 | O10: =O11*O4 -> 1824.7865 | ... Q10: =Q11*Q4 -> 1714.1695
B11: %rev | C11: =C10/C4 -> 0.018188369 | D11: =D10/D4 -> 0.017014947 | E11: =E10/E4 -> 0.018740284 | F11: =F10/F4 -> 0.019154496 | G11: =G10/G4 -> 0.021937578 | H11: =AVERAGE($C$11:$G$11)+0.03 -> 0.049007135 | I11: =AVERAGE($C$11:$G$11)+0.03 -> 0.049007135 | J11: =AVERAGE($C$11:$G$11)+0.025 -> 0.044007135 | K11: =AVERAGE($C$11:$G$11)+0.025 -> 0.044007135 | L11: =AVERAGE($C$11:$G$11)+0.02 -> 0.039007135 | M11: =AVERAGE($C$11:$G$11)+0.017 -> 0.036007135 | N11: =AVERAGE($C$11:$G$11)+0.01 -> 0.029007135 | O11: =AVERAGE($C$11:$G$11)+0.01 -> 0.029007135 | P11: =AVERAGE($C$11:$G$11)+0.008 -> 0.027007135 | Q11: =AVERAGE($C$11:$G$11)+0.006 -> 0.025007135
B12: (-) CapEx | C12: -784.8 | D12: -1028 | E12: -1070.5 | F12: -1560.6 | G12: -1700.2 | H12: =H13*H4 -> -2758.6768 | I12: =I13*I4 -> -2924.2575 | J12: =J13*J4 -> -2720.264 | K12: =K13*K4 -> -2541.6007 | L12: =L13*L4 -> -2415.8778 | M12: =M13*M4 -> -2288.979 | N12: =N13*N4 -> -2164.9437 | O12: =O13*O4 -> -1950.1541 | ... Q12: =Q13*Q4 -> -1714.1671
B13: %rev | C13: =C12/C4 -> -0.028277005 | D13: =D12/D4 -> -0.030462148 | E13: =E12/E4 -> -0.03128251 | F13: =F12/F4 -> -0.041236732 | G13: =G12/G4 -> -0.043942354 | H13: =-6.5% -> -0.065 | I13: -0.065 | J13: =AVERAGE($C$13:$G$13)-0.022 -> -0.05704015 | K13: =AVERAGE($C$13:$G$13)-0.015 -> -0.05004015 | L13: -0.045 | M13: -0.04 | N13: -0.036 | O13: -0.031 | P13: -0.028 | Q13: -0.0250071
B14: NWC | C14: ='NWC Build'!E20 -> 394.543 | D14: ='NWC Build'!F20 -> -173.141 | E14: ='NWC Build'!G20 -> -20.343 | F14: ='NWC Build'!H20 -> 1311.665 | G14: ='NWC Build'!I20 -> 1516.385 | H14: ='NWC Build'!J20 -> 262.65366 | I14: ='NWC Build'!K20 -> -164.98008 | J14: ='NWC Build'!L20 -> 160.1978 | ... Q14: ='NWC Build'!S20 -> 250.50904
B15: %rev | C15: =C14/C4 -> 0.014215717 | D15: =D14/D4 -> -0.0051305902 | E15: =E14/E4 -> -0.00059446997 | F15: =F14/F4 -> 0.034658963 | G15: =G14/G4 -> 0.039191582 | H15: =H14/H4 -> 0.0061886511 | I15: =I14/I4 -> -0.0036671548 | J15: =J14/J4 -> 0.0033591248 | ... Q15: =Q14/Q4 -> 0.0036545472
B16: Change in NWC | C16: 0 | D16: =D14-C14 -> -567.684 | E16: =E14-D14 -> 152.798 | F16: =F14-E14 -> 1332.008 | G16: =G14-F14 -> 204.72 | H16: =H14-G14 -> -1253.7313 | I16: =I14-H14 -> -427.63374 | J16: =J14-I14 -> 325.17787 | K16: =K14-J14 -> 248.43336 | ... Q16: =Q14-P14 -> 191.94798
B17: FCF | C17: 0 | D17: =D8+D10+D12-D16 -> 2902.964 | E17: =E8+E10+E12-E16 -> 1945.0692 | F17: =F8+F10+F12-F16 -> 443.3256 | G17: =G8+G10+G12-G16 -> 867.032 | H17: =H8+H10+H12-H16 -> 2797.6708 | I17: =I8+I10+I12-I16 -> 2240.5985 | J17: =J8+J10+J12-J16 -> 1849.9872 | K17: =K8+K10+K12-K16 -> 2423.7026 | ... Q17: =Q8+Q10+Q12-Q16 -> 4096.5877
B18: Discounted FCF | C18: 0 | D18: 0 | E18: 0 | F18: 0 | G18: 0 | H18: =H17/(1+$C38)^(H3-$G3) -> 2600.9613 | I18: =I17/(1+$C38)^(I3-$G3) -> 1936.594 | J18: =J17/(1+$C38)^(J3-$G3) -> 1486.5535 | K18: =K17/(1+$C38)^(K3-$G3) -> 1810.6245 | L18: =L17/(1+$C38)^(L3-$G3) -> 2035.4678 | M18: =M17/(1+$C38)^(M3-$G3) -> 2472.9802 | N18: =N17/(1+$C38)^(N3-$G3) -> 1949.2942 | O18: =O17/(1+$C38)^(O3-$G3) -> 2001.7461 | ... Q18: =Q17/(1+$C38)^(Q3-$G3) -> 1976.0365
B20: WACC Calculation | E20: Terminal Value: Gordon Growth Method | I20: Terminal Value: Exit Multiples Method
B21: Risk Free | C21: 0.0467 | E21: Terminal Growth Rate | G21: 0.02 | I21: Median EV/EBITDA | K21: =Comps!K12 -> 13.092305 | O21: FINAL YEAR EBITDA
B22: Unlevered Beta | C22: 1.13 | E22: Terminal Value | G22: =Q17*((1+G21)/(C38-G21)) -> 75113.292 | I22: Terminal Value | K22: =O22*K21 -> 49173.367 | O22: =Q6-Q10 -> 3755.8984
B23: Levered Beta | C23: 1.32 | E23: Present Value of TV | G23: =G22/((1+C38)^(L3-G3)) -> 52167.876 | I23: Present Value of TV | K23: =K22/((1+C38)^(Q3-G3)) -> 23719.343
B24: Equity Risk Premium | C24: 0.0457 | E24: Sum of Near Term Cash Flows | G24: =SUM(H18:Q18) -> 20442.183 | I24: =E24 -> Sum of Near Term Cash Flows | K24: =SUM(H18:Q18) -> 20442.183
E25: Implied Enterprise Value | G25: =G24+G23 -> 72610.059 | I25: =E25 -> Implied Enterprise Value | K25: =K24+K23 -> 44161.526
B26: Effective Tax Rate | C26: =0.216 -> 0.216 | E26: Implied Equity Value | G26: =G25-$C34 -> 68986.359 | I26: =E26 -> Implied Equity Value | K26: =K25-$C34 -> 40537.826
B27: Cost of Equity | C27: =C21+C23*(C24) -> 0.107024 | E27: Implied Share Price | G27: =G26/$C30 -> 334.39825 | I27: =E27 -> Implied Share Price | K27: =K26/$C30 -> 196.4994
B28: Cost of Debt | C28: =5.8%*(1-C26) -> 0.045472 | E28: Upside | G28: =(G27-$C29)/$C29 -> 1.1662127 | I28: Upside | K28: =(K27-$C29)/$C29 -> 0.27291184
B29: Current Stock Price | C29: 154.37 | I29: =E29 -> 0
B30: Shares Outstanding | C30: 206.3
B31: Market Cap | C31: 3976.7
B33: Total Debt | C33: 4139.8
B34: Net Debt | C34: 3623.7
B35: Market Cap | C35: =C31 -> 3976.7
B36: Percent Equity | C36: =C35/(C33+C35) -> 0.48995257
B37: Percent Debt | C37: =1-C36 -> 0.51004743
B38: WACC | C38: =C36*C27+C28*C37 -> 0.07562956

Sheet Revenue Build (Bear Case)
A1: * add popshelf as separate line items
E2: Revenue Model
E3: Historical | J3: Projected
B4: Year | E4: 2019 | F4: 2020 | G4: 2021 | H4: 2022 | I4: 2023 | J4: 2024 | K4: 2025 | L4: 2026 | M4: 2027 | N4: 2028 | O4: =N4+1 -> 2029 | P4: =O4+1 -> 2030 | Q4: =P4+1 -> 2031 | R4: =Q4+1 -> 2032 | S4: =R4+1 -> 2033
B5: # of New and Acquired Stores (U.S.) | E5: 975 | F5: 1000 | G5: 1050 | H5: 1039 | I5: 744 | J5: 700 | K5: 720 | L5: 750 | M5: 700 | N5: 700 | O5: 680 | P5: 650 | Q5: 600 | R5: 580 | S5: 550 | T5: BEAR CASE:
B6: # of New And Acquired Stores (Mexico) | E6: 0 | F6: 0 | G6: 0 | H6: 0 | I6: 3 | J6: 10 | K6: 10 | L6: 10 | M6: 15 | N6: 15 | O6: 15 | P6: 10 | Q6: 10 | R6: 10 | S6: 5 | T6: - PopShelf tanks; doesn't attract the customer base Vasos wants; still growt in the number of stores, just not at a very high rate year over year
B7: # of New PopShelf Stores | I7: 240 | J7: 250 | K7: 250 | L7: 200 | M7: 180 | N7: 150 | O7: 120 | P7: 120 | Q7: 90 | R7: 75 | S7: 40 | T7: - more store closure, due to initiatives to fix shrink and poor bloated inventory failing
B8: # of New and Acquired Stores (Total) | E8: =E5+E6 -> 975 | F8: =F5+F6 -> 1000 | G8: =G5+G6 -> 1050 | H8: =H5+H6 -> 1039 | I8: =I5+I6+I7 -> 987 | J8: =J5+J6+J7 -> 960 | K8: =K5+K6+K7 -> 980 | L8: =L5+L6+L7 -> 960 | M8: =M5+M6+M7 -> 895 | N8: =N5+N6+N7 -> 865 | O8: =O5+O6+O7 -> 815 | P8: =P5+P6+P7 -> 780 | ... S8: =S5+S6+S7 -> 595 | T8: - Possible distrust starting to grow with Vasos, whose statements can be seen as a bit
B9: # of Closed Stores | E9: 67 | F9: 101 | G9: 97 | H9: 65 | I9: 105 | J9: 95 | K9: 100 | L9: 100 | M9: 120 | N9: 120 | O9: 130 | P9: 130 | Q9: 140 | R9: 145 | S9: 150 | T9: too optimistic given the poor economic year DG just went through in 2023
B11: # of Beginning Stores | E11: =15370 -> 15370 | F11: =E15 -> 16278 | G11: =F15 -> 17177 | H11: =G15 -> 18130 | I11: =H15 -> 19104 | J11: =I15 -> 19986 | K11: =J15 -> 20851 | L11: =K15 -> 21731 | M11: =L15 -> 22591 | ... S11: =R15 -> 26526 | T11: - very low rate of growth; inventory not being distributed as well as the company wants,
B12: # of New and Acquired Stores | E12: =E8 -> 975 | F12: =F8 -> 1000 | G12: =G8 -> 1050 | H12: =H8 -> 1039 | I12: =I8 -> 987 | J12: =J8 -> 960 | K12: =K8 -> 980 | L12: =L8 -> 960 | ... S12: =S8 -> 595 | T12: cutting back on concrete efforts to expand selling space so as to minimize operating costs
B13: # of Closed Stores | E13: =E9 -> 67 | F13: =F9 -> 101 | G13: =G9 -> 97 | H13: =H9 -> 65 | I13: =I9 -> 105 | J13: =J9 -> 95 | K13: =K9 -> 100 | L13: =L9 -> 100 | ... S13: =S9 -> 150 | T13: - does not meet goal of expanding stores (~8500 t0 9000 sq ft)
B14: Closed Stores Proportion | E14: =E13/E11 -> 0.0043591412 | F14: =F13/F11 -> 0.0062046935 | G14: =G13/G11 -> 0.0056470862 | H14: =H13/H11 -> 0.0035852179 | I14: =I13/I11 -> 0.0054962312 | J14: =J13/J11 -> 0.0047533273 | K14: =K13/K11 -> 0.004795933 | L14: =L13/L11 -> 0.004601721 | ... S14: =S13/S11 -> 0.0056548292
B15: # of Ending Stores | E15: =E11+E12-E13 -> 16278 | F15: =F11+F12-F13 -> 17177 | G15: =G11+G12-G13 -> 18130 | H15: =H11+H12-H13 -> 19104 | I15: =I11+I12-I13 -> 19986 | J15: =J11+J12-J13 -> 20851 | K15: =K11+K12-K13 -> 21731 | L15: =L11+L12-L13 -> 22591 | ... S15: =S11+S12-S13 -> 26971 | T15: - shrink and inventory problems are not properly tackled; sales per square foot decreases year over year
B16: Growth Rate in # of Stores | E16: - | F16: =(F15-E15)/E15 -> 0.055227915 | G16: =(G15-F15)/F15 -> 0.055481167 | H16: =(H15-G15)/G15 -> 0.053723111 | I16: =(I15-H15)/H15 -> 0.046168342 | J16: =(J15-I15)/I15 -> 0.043280296 | K16: =(K15-J15)/J15 -> 0.042204211 | L16: =(L15-K15)/K15 -> 0.039574801 | M16: =(M15-L15)/L15 -> 0.034305697 | ... S16: =(S15-R15)/R15 -> 0.016775993 | T16: after 2026 - the year in which PopShelf is projected to reach its peak (same assumption here, we just assume the peak isn't as high
B17: Selling Square Footage (in thousands) | E17: 120342 | F17: 127056 | G17: 134532 | H17: 142987 | I17: 151095 | J17: =ROUND(I17*(1+J18), 0) -> 158801 | K17: =ROUND(J17*(1+K18), 0) -> 166265 | L17: =ROUND(K17*(1+L18), 0) -> 174079 | M17: =ROUND(L17*(1+M18), 0) -> 181390 | N17: =ROUND(M17*(1+N18), 0) -> 188101 | O17: =ROUND(N17*(1+O18), 0) -> 194685 | P17: =ROUND(O17*(1+P18), 0) -> 200720 | Q17: =ROUND(P17*(1+Q18), 0) -> 205939 | ... S17: =ROUND(R17*(1+S18), 0) -> 214680 | T17: - revenue takes a hit due to poor sales and lack of following through on promises
B18: Growth Rate of Selling Square Footage | E18: - | F18: 0.056 | G18: 0.059 | H18: 0.063 | I18: 0.057 | J18: 0.051 | K18: 0.047 | L18: 0.047 | M18: 0.042 | N18: 0.037 | O18: 0.035 | P18: 0.031 | Q18: 0.026 | R18: 0.021 | S18: 0.021 | T18: made by the company's board; we may see store closures like Dollar Tree in the near future given this case...
B19: Average Square Foot per Store | E19: =ROUND((E17/E15)*1000, 0) -> 7393 | F19: =ROUND((F17/F15)*1000, 0) -> 7397 | G19: =ROUND((G17/G15)*1000, 0) -> 7420 | H19: =ROUND((H17/H15)*1000, 0) -> 7485 | I19: =ROUND((I17/I15)*1000, 0) -> 7560 | J19: =ROUND((J17/J15)*1000, 0) -> 7616 | K19: =ROUND((K17/K15)*1000, 0) -> 7651 | L19: =ROUND((L17/L15)*1000, 0) -> 7706 | ... S19: =ROUND((S17/S15)*1000, 0) -> 7960
B20: Growth Rate of Average Square Foot per Store | E20: - | F20: =(F19-E19)/E19 -> 0.00054105235 | G20: =(G19-F19)/F19 -> 0.0031093687 | H20: =(H19-G19)/G19 -> 0.0087601078 | I20: =(I19-H19)/H19 -> 0.01002004 | J20: =(J19-I19)/I19 -> 0.0074074074 | K20: =(K19-J19)/J19 -> 0.0045955882 | L20: =(L19-K19)/K19 -> 0.0071886028 | M20: =(M19-L19)/L19 -> 0.0073968336 | ... S20: =(S19-R19)/R19 -> 0.0041629873
B21: Average Sales per Square Foot | E21: 237 | F21: 273 | G21: 262 | H21: 273 | I21: 264 | J21: 265 | K21: 263 | L21: 267 | M21: 262 | N21: 258 | O21: 247 | P21: 237 | Q21: 223 | R21: 215 | S21: 210
B22: Growth Rate of Average Sales per Square Foot | E22: - | F22: =(F21-E21)/E21 -> 0.15189873 | G22: =(G21-F21)/F21 -> -0.04029304 | H22: =(H21-G21)/G21 -> 0.041984733 | I22: =(I21-H21)/H21 -> -0.032967033 | J22: =(J21-I21)/I21 -> 0.0037878788 | K22: =(K21-J21)/J21 -> -0.0075471698 | L22: =(L21-K21)/K21 -> 0.015209125 | M22: =(M21-L21)/L21 -> -0.018726592 | ... S22: =(S21-R21)/R21 -> -0.023255814
B23: Revenue Projections | J23: =J19*J15*J21 -> 42082322240 | K23: =K19*K15*K21 -> 43727400703 | L23: =L19*L15*L21 -> 46481027682 | M23: =M19*M15*M21 -> 47524247596 | N23: =N19*N15*N21 -> 48527197038 | O23: =O19*O15*O21 -> 48084328812 | P23: =P19*P15*P21 -> 47570177376 | Q23: =Q19*Q15*Q21 -> 45924957622 | ... S23: =S19*S15*S21 -> 45084723600
B28: Total Revenue | E28: 27754 | F28: 33746.8 | G28: 34220.4 | H28: 37844.9 | I28: 38691.6 | J28: =J23/1000000 -> 42082.322 | K28: =K23/1000000 -> 43727.401 | L28: =L23/1000000 -> 46481.028 | M28: =M23/1000000 -> 47524.248 | N28: =N23/1000000 -> 48527.197 | O28: =O23/1000000 -> 48084.329 | P28: =P23/1000000 -> 47570.177 | Q28: =Q23/1000000 -> 45924.958 | ... S28: =S23/1000000 -> 45084.724
B29: Growth Rate of Total Revenue | E29: - | F29: =(F28-E28)/E28 -> 0.21592563 | G29: =(G28-F28)/F28 -> 0.014033923 | H29: =(H28-G28)/G28 -> 0.10591635 | I29: =(I28-H28)/H28 -> 0.022372896 | J29: =(J28-I28)/I28 -> 0.087634583 | K29: =(K28-J28)/J28 -> 0.039091913 | L29: =(L28-K28)/K28 -> 0.062972574 | M29: =(M28-L28)/L28 -> 0.022443994 | ... S29: =(S28-R28)/R28 -> -0.0027355723 | T29: - projected revenue loss yoy beginning FY 2029; long term issues of shrink and inventory are not properly tackled
B30: COGS + Operating Costs | E30: =(1-0.32)*E28 -> 18872.72 | F30: =(1-0.32)*F28 -> 22947.824 | G30: =(1-0.32)*G28 -> 23269.872 | H30: =(1-0.32)*H28 -> 25734.532 | I30: =(1-0.32)*I28 -> 26310.288 | J30: =(1-0.32)*J28 -> 28615.979 | K30: =(1-0.32)*K28 -> 29734.632 | L30: =(1-0.32)*L28 -> 31607.099 | ... S30: =(1-0.32)*S28 -> 30657.612 | T30: Vasos' reappointment, which appears good on paper, has not worked to put the company back on track
B31: Total Store Sales by Segment | T31: following Owen's disastrous tenure; warning signs before this revenue loss include
B32: % Sales of Consumables | E32: 0.78 | F32: 0.768 | G32: 0.767 | H32: 0.797 | I32: 0.81 | J32: 0.81 | K32: 0.81 | L32: 0.815 | M32: 0.815 | N32: 0.82 | T32: poor Popshelf performance, stagnant to no growth in Mexico (international) sector
B33: Growth Rate of Consumables Sales | E33: - | F33: =(F32-E32)/E32 -> -0.015384615 | G33: =(G32-F32)/F32 -> -0.0013020833 | H33: =(H32-G32)/G32 -> 0.039113429 | I33: =(I32-H32)/H32 -> 0.016311167 | J33: =(J32-I32)/I32 -> 0 | K33: =(K32-J32)/J32 -> 0 | L33: =(L32-K32)/K32 -> 0.0061728395 | M33: =(M32-L32)/L32 -> 0 | N33: =(N32-M32)/M32 -> 0.0061349693 | T33: representative of the company trying to tackle intrinsic store-related problems by opening stores in
B34: % Sales of Seasonal | E34: 0.117 | F34: 0.121 | G34: 0.122 | H34: 0.11 | I34: 0.106 | J34: 0.105 | K34: 0.105 | L34: 0.1 | M34: 0.1 | N34: 0.095 | T34: a new location (doesn't project to work out in this case)
B35: Growth Rate of Seasonal Sales | E35: - | F35: =(F34-E34)/E34 -> 0.034188034 | G35: =(G34-F34)/F34 -> 0.0082644628 | H35: =(H34-G34)/G34 -> -0.098360656 | I35: =(I34-H34)/H34 -> -0.036363636 | J35: =(J34-I34)/I34 -> -0.0094339623 | K35: =(K34-J34)/J34 -> 0 | L35: =(L34-K34)/K34 -> -0.047619048 | M35: =(M34-L34)/L34 -> 0 | N35: =(N34-M34)/M34 -> -0.05 | T35: - DG will always be a staple for low-income communities for customers with no alternate options,
B36: % Sales of Home Products | E36: 0.058 | F36: 0.065 | G36: 0.068 | H36: 0.062 | I36: 0.056 | J36: 0.055 | K36: 0.055 | L36: 0.053 | M36: 0.051 | N36: 0.051 | T36: which explains why rev loss percentage yoy is never above 3-4%; however, this loss
B37: Growth Rate of Home Products Sales | E37: - | F37: =(F36-E36)/E36 -> 0.12068966 | G37: =(G36-F36)/F36 -> 0.046153846 | H37: =(H36-G36)/G36 -> -0.088235294 | I37: =(I36-H36)/H36 -> -0.096774194 | J37: =(J36-I36)/I36 -> -0.017857143 | K37: =(K36-J36)/J36 -> 0 | L37: =(L36-K36)/K36 -> -0.036363636 | M37: =(M36-L36)/L36 -> -0.037735849 | N37: =(N36-M36)/M36 -> 0 | T37: in revenue should explain our bearish assumptions that Vasos' reappointment
B38: % Sales of Apparel | E38: 0.045 | F38: 0.046 | G38: 0.043 | H38: 0.031 | I38: 0.028 | J38: =1-J36-J34-J32 -> 0.03 | K38: =1-K36-K34-K32 -> 0.03 | L38: =1-L36-L34-L32 -> 0.032 | M38: =1-M36-M34-M32 -> 0.034 | N38: =1-N36-N34-N32 -> 0.034 | T38: has a possibility of not fulfilling the company's current high hopes surrounding
B39: Growth Rate of Apparel Sales | E39: - | F39: =(F38-E38)/E38 -> 0.022222222 | G39: =(G38-F38)/F38 -> -0.065217391 | H39: =(H38-G38)/G38 -> -0.27906977 | I39: =(I38-H38)/H38 -> -0.096774194 | J39: =(J38-I38)/I38 -> 0.071428571 | K39: =(K38-J38)/J38 -> 0 | L39: =(L38-K38)/K38 -> 0.066666667 | M39: =(M38-L38)/L38 -> 0.0625 | N39: =(N38-M38)/M38 -> 0 | T39: solving poor 2022-23 finances, as well as on-paper statements about tackling shrink, bloated inventory, and
T40: fluctuating sales per square foot

Sheet DCF (Bear Case)
A1: All numbers in millions of dollars. | B1: Historical | G1: Projected
A2: Year | B2: 2019 | C2: 2020 | D2: 2021 | E2: 2022 | F2: 2023 | G2: 2024 | H2: 2025 | I2: 2026 | J2: 2027 | K2: 2028 | L2: 2029 | M2: 2030 | N2: 2031 | O2: 2032 | P2: 2033
A3: Revenue | B3: ='Revenue Build (Base Case)'!E28 -> 27754 | C3: ='Revenue Build (Base Case)'!F28 -> 33746.8 | D3: ='Revenue Build (Base Case)'!G28 -> 34220.4 | E3: ='Revenue Build (Base Case)'!H28 -> 37844.9 | F3: ='Revenue Build (Base Case)'!I28 -> 38691.6 | G3: ='Revenue Build (Bear Case)'!J28 -> 42082.322 | H3: ='Revenue Build (Bear Case)'!K28 -> 43727.401 | I3: ='Revenue Build (Bear Case)'!L28 -> 46481.028 | J3: ='Revenue Build (Bear Case)'!M28 -> 47524.248 | K3: ='Revenue Build (Bear Case)'!N28 -> 48527.197 | L3: ='Revenue Build (Bear Case)'!O28 -> 48084.329 | M3: ='Revenue Build (Bear Case)'!P28 -> 47570.177 | N3: ='Revenue Build (Bear Case)'!Q28 -> 45924.958 | ... P3: ='Revenue Build (Bear Case)'!S28 -> 45084.724
A4: revenue growth | B4: 0.083 | C4: 0.216 | D4: 0.014 | E4: 0.106 | F4: 0.022 | G4: =(G3-F3)/F3 -> 0.087634583 | H4: =(H3-G3)/G3 -> 0.039091913 | I4: =(I3-H3)/H3 -> 0.062972574 | J4: =(J3-I3)/I3 -> 0.022443994 | K4: =(K3-J3)/J3 -> 0.021103952 | L4: =(L3-K3)/K3 -> -0.009126186 | M4: =(M3-L3)/L3 -> -0.010692703 | N4: =(N3-M3)/M3 -> -0.034585109 | ... P4: =(P3-O3)/O3 -> -0.0027355723
A5: EBIT | B5: 2336.9 | C5: 3557.5 | D5: 3223.3 | E5: 3330.4 | F5: 2453 | G5: =G3*G6 -> 2811.0991 | H5: =H3*H6 -> 2483.7164 | I5: =I3*I6 -> 2640.1224 | J5: =J3*J6 -> 2224.1348 | K5: =K3*K6 -> 2271.0728 | L5: =L3*L6 -> 2250.3466 | M5: =M3*M6 -> 1988.4334 | N5: =N3*N6 -> 1919.6632 | ... P5: =P3*P6 -> 1577.9653
A6: %rev | B6: 0.084 | C6: 0.105 | D6: 0.094 | E6: 0.088 | F6: 0.063 | G6: =AVERAGE(B6:F6)-0.02 -> 0.0668 | H6: =G6-0.01 -> 0.0568 | I6: =H6 -> 0.0568 | J6: =I6-0.01 -> 0.0468 | K6: =J6 -> 0.0468 | L6: =K6 -> 0.0468 | M6: 0.0418 | N6: 0.0418 | O6: 0.038 | P6: 0.035
A7: NOPAT | B7: =B5*(1-$B23) -> 2230.1037 | C7: =C5*(1-$B23) -> 3394.9223 | D7: =D5*(1-$B23) -> 3075.9952 | E7: =E5*(1-$B23) -> 3178.2007 | F7: =F5*(1-$B23) -> 2340.8979 | G7: =G5*(1-$B25) -> 2203.9017 | H7: =H5*(1-$B25) -> 1947.2336 | I7: =I5*(1-$B25) -> 2069.8559 | J7: =J5*(1-$B25) -> 1743.7217 | K7: =K5*(1-$B25) -> 1780.5211 | L7: =L5*(1-$B25) -> 1764.2717 | M7: =M5*(1-$B25) -> 1558.9318 | N7: =N5*(1-$B25) -> 1505.016 | ... P7: =P5*(1-$B25) -> 1237.1248
A8: %rev | B8: =B7/B3 -> 0.080352514 | C8: =C7/C3 -> 0.10059983 | D8: =D7/D3 -> 0.089887763 | E8: =E7/E3 -> 0.083979631 | F8: =F7/F3 -> 0.06050145 | G8: =G7/G3 -> 0.0523712 | H8: =H7/H3 -> 0.0445312 | I8: =I7/I3 -> 0.0445312 | ... P8: =P7/P3 -> 0.02744
A9: (+) D&A | B9: 504.8 | C9: 574.2 | D9: 641.3 | E9: 724.9 | F9: 848.8 | G9: =G10*G3 -> 2062.334 | H9: =H10*H3 -> 2412.4795 | I9: =I10*I3 -> 2556.4565 | J9: =J10*J3 -> 2376.2124 | K9: =K10*K3 -> 2426.3599 | L9: =L10*L3 -> 2308.0478 | M9: =M10*M3 -> 2283.3685 | N9: =N10*N3 -> 2112.5481 | ... P9: =P10*P3 -> 2028.8126
A10: %rev | B10: =B9/B3 -> 0.018188369 | C10: =C9/C3 -> 0.017014947 | D10: =D9/D3 -> 0.018740284 | E10: =E9/E3 -> 0.019154496 | F10: =F9/F3 -> 0.021937578 | G10: =AVERAGE(B10:F10)+0.03 -> 0.049007135 | H10: =AVERAGE(C10:G10)+0.03 -> 0.055170888 | I10: 0.055 | J10: 0.05 | K10: 0.05 | L10: 0.048 | M10: 0.048 | N10: 0.046 | O10: 0.046 | P10: 0.045
A11: (-) CapEx | B11: -784.8 | C11: -1028 | D11: -1070.5 | E11: -1560.6 | F11: -1700.2 | G11: =G12*G3 -> -2735.3509 | H11: =H12*H3 -> -2842.281 | I11: =I12*I3 -> -2491.3881 | J11: =J12*J3 -> -2719.2278 | K11: =K12*K3 -> -2719.4599 | L11: =L12*L3 -> -2404.2164 | M11: =M12*M3 -> -2378.5089 | N11: =N12*N3 -> -2204.398 | ... P11: =P12*P3 -> -2028.8126
A12: %rev | B12: =B11/B3 -> -0.028277005 | C12: =C11/C3 -> -0.030462148 | D12: =D11/D3 -> -0.03128251 | E12: =E11/E3 -> -0.041236732 | F12: =F11/F3 -> -0.043942354 | G12: -0.065 | H12: -0.065 | I12: =AVERAGE(B12:H12)-0.01 -> -0.053600107 | J12: =AVERAGE(C12:I12)-0.01 -> -0.057217693 | K12: =AVERAGE(D12:J12)-0.005 -> -0.056039914 | L12: -0.05 | M12: -0.05 | N12: -0.048 | O12: -0.046 | P12: -0.045
A13: NWC | B13: ='NWC Build'!E20 -> 394.543 | C13: ='NWC Build'!F20 -> -173.141 | D13: ='NWC Build'!G20 -> -20.343 | E13: ='NWC Build'!H20 -> 1311.665 | F13: ='NWC Build'!I20 -> 1516.385 | G13: ='NWC Build'!J20 -> 262.65366 | H13: ='NWC Build'!K20 -> -164.98008 | I13: ='NWC Build'!L20 -> 160.1978 | ... P13: ='NWC Build'!S20 -> 250.50904
A14: %rev | B14: =B13/B3 -> 0.014215717 | C14: =C13/C3 -> -0.0051305902 | D14: =D13/D3 -> -0.00059446997 | E14: =E13/E3 -> 0.034658963 | F14: =F13/F3 -> 0.039191582 | G14: =G13/G3 -> 0.0062414251 | H14: =H13/H3 -> -0.0037729221 | I14: =I13/I3 -> 0.0034465201 | ... P14: =P13/P3 -> 0.0055564063
A15: Change in NWC | B15: 0 | C15: =C13-B13 -> -567.684 | D15: =D13-C13 -> 152.798 | E15: =E13-D13 -> 1332.008 | F15: =F13-E13 -> 204.72 | G15: =G13-F13 -> -1253.7313 | H15: =H13-G13 -> -427.63374 | I15: =I13-H13 -> 325.17787 | J15: =J13-I13 -> 248.43336 | ... P15: =P13-O13 -> 191.94798
A16: FCF | B16: 0 | C16: =C7+C9+C11-C15 -> 3508.8063 | D16: =D7+D9+D11-D15 -> 2493.9972 | E16: =E7+E9+E11-E15 -> 1010.4927 | F16: =F7+F9+F11-F15 -> 1284.7779 | G16: =G7+G9+G11-G15 -> 2784.6161 | H16: =H7+H9+H11-H15 -> 1945.0658 | I16: =I7+I9+I11-I15 -> 1809.7465 | J16: =J7+J9+J11-J15 -> 1152.2729 | ... P16: =P7+P9+P11-P15 -> 1045.1768
A17: Discounted FCF | B17: 0 | C17: 0 | D17: 0 | E17: 0 | F17: 0 | G17: =G16/((1+$B$37)^(G2-$F$2)) -> 2588.8245 | H17: =H16/((1+$B$37)^(H2-$F$2)) -> 1681.1592 | I17: =I16/((1+$B$37)^(I2-$F$2)) -> 1454.2182 | J17: =J16/((1+$B$37)^(J2-$F$2)) -> 860.8043 | K17: =K16/((1+$B$37)^(K2-$F$2)) -> 1046.9163 | L17: =L16/((1+$B$37)^(L2-$F$2)) -> 1385.9276 | M17: =M16/((1+$B$37)^(M2-$F$2)) -> 821.91421 | N17: =N16/((1+$B$37)^(N2-$F$2)) -> 663.90893 | ... P17: =P16/((1+$B$37)^(P2-$F$2)) -> 504.15315
A19: WACC Calculation | D19: Terminal Value: Gordon Growth Method | H19: Terminal Value: Exit Multiples Method
A20: Risk Free | B20: 0.0467 | D20: Terminal Growth Rate | F20: 0.02 | H20: Median EV/EBITDA | J20: =Comps!K12 -> 13.092305 | N20: FINAL YEAR EBITDA
A21: Unlevered Beta | B21: 1.13 | D21: Terminal Value | F21: =P16*((1+F20)/(B37-F20)) -> 19163.919 | H21: Terminal Value | J21: =N21*J20 -> -5902.6295 | N21: =P5-P9 -> -450.84724
A22: Levered Beta | B22: 1.32 | D22: Present Value of TV | F22: =F21/((1+B37)^(K2-F2)) -> 13309.774 | H22: Present Value of TV | J22: =J21/((1+B37)^(P2-F2)) -> -2847.2017
A23: Equity Risk Premium | B23: 0.0457 | D23: Sum of Near Term Cash Flows | F23: =SUM(G17:P17) -> 11794.785 | H23: =D23 -> Sum of Near Term Cash Flows | J23: =SUM(G17:P17) -> 11794.785
D24: Implied Enterprise Value | F24: =F23+F22 -> 25104.558 | H24: =D24 -> Implied Enterprise Value | J24: =J23+J22 -> 8947.5828
A25: Effective Tax Rate | B25: =0.216 -> 0.216 | D25: Implied Equity Value | F25: =F24-$B33 -> 21480.858 | H25: =D25 -> Implied Equity Value | J25: =J24-$B33 -> 5323.8828
A26: Cost of Equity | B26: =B20+B22*(B23) -> 0.107024 | D26: Implied Share Price | F26: =F25/$B29 -> 104.12437 | H26: =D26 -> Implied Share Price | J26: =J25/$B29 -> 25.806509
A27: Cost of Debt | B27: =5.8%*(1-B25) -> 0.045472 | D27: Upside | F27: =(F26-$B28)/$B28 -> -0.32548828 | H27: Upside | J27: =(J26-$B28)/$B28 -> -0.83282691
A28: Current Stock Price | B28: 154.37
A29: Shares Outstanding | B29: 206.3
A30: Market Cap | B30: 3976.7
A32: Total Debt | B32: 4139.8
A33: Net Debt | B33: 3623.7
A34: Market Cap | B34: =B30 -> 3976.7
A35: Percent Equity | B35: =B34/(B32+B34) -> 0.48995257
A36: Percent Debt | B36: =1-B35 -> 0.51004743
A37: WACC | B37: =B35*B26+B27*B36 -> 0.07562956

Sheet Revenue Build (Bull Case)
A1: * add popshelf as separate line items
E2: Revenue Model
E3: Historical | J3: Projected
B4: Year | E4: 2019 | F4: 2020 | G4: 2021 | H4: 2022 | I4: 2023 | J4: 2024 | K4: 2025 | L4: 2026 | M4: 2027 | N4: 2028 | O4: =N4+1 -> 2029 | P4: =O4+1 -> 2030 | Q4: =P4+1 -> 2031 | R4: =Q4+1 -> 2032 | S4: =R4+1 -> 2033
B5: # of New and Acquired Stores (U.S.) | E5: 975 | F5: 1000 | G5: 1050 | H5: 1039 | I5: 744 | J5: 700 | K5: 720 | L5: 750 | M5: 750 | N5: 750 | O5: 780 | P5: 780 | Q5: 800 | R5: 800 | S5: 800 | T5: BULL CASE:
B6: # of New And Acquired Stores (Mexico) | E6: 0 | F6: 0 | G6: 0 | H6: 0 | I6: 3 | J6: 15 | K6: 20 | L6: 35 | M6: 40 | N6: 55 | O6: 65 | P6: 75 | Q6: 90 | R6: 100 | S6: 115 | T6: - Mexican market loves DG - low operating costs also prove advantageous for the company to not only fix its operating margin, but also allows it to employ more employees to combat shrink and aligns with effots to remove self-checkout
B7: # of New PopShelf Stores | I7: 240 | J7: 250 | K7: 250 | L7: 250 | M7: 280 | N7: 280 | O7: 320 | P7: 360 | Q7: 400 | R7: 450 | S7: 480 | T7: - we believe Mexico is a promising aspect of DG's future plans that is currently not priced in, given little to no talks or activity about Mexican expansion
B8: # of New and Acquired Stores (Total) | E8: =E5+E6 -> 975 | F8: =F5+F6 -> 1000 | G8: =G5+G6 -> 1050 | H8: =H5+H6 -> 1039 | I8: =I5+I6+I7 -> 987 | J8: =J5+J6+J7 -> 965 | K8: =K5+K6+K7 -> 990 | L8: =L5+L6+L7 -> 1035 | M8: =M5+M6+M7 -> 1070 | N8: =N5+N6+N7 -> 1085 | O8: =O5+O6+O7 -> 1165 | P8: =P5+P6+P7 -> 1215 | ... S8: =S5+S6+S7 -> 1395 | T8: in any recent earnings calls, reports, or research, coupled with slow growth to begin with under Vasos' return
B9: # of Closed Stores | E9: 67 | F9: 101 | G9: 97 | H9: 65 | I9: 105 | J9: =AVERAGE($F9:$I9) -> 92 | K9: 95 | L9: 100 | M9: 95 | N9: 92 | O9: 85 | P9: 80 | Q9: 80 | R9: 75 | S9: 70
B11: # of Beginning Stores | E11: =15370 -> 15370 | F11: =E15 -> 16278 | G11: =F15 -> 17177 | H11: =G15 -> 18130 | I11: =H15 -> 19104 | J11: =I15 -> 19986 | K11: =J15 -> 20859 | L11: =K15 -> 21754 | M11: =L15 -> 22689 | ... S11: =R15 -> 29357
B12: # of New and Acquired Stores | E12: =E8 -> 975 | F12: =F8 -> 1000 | G12: =G8 -> 1050 | H12: =H8 -> 1039 | I12: =I8 -> 987 | J12: =J8 -> 965 | K12: =K8 -> 990 | L12: =L8 -> 1035 | ... S12: =S8 -> 1395
B13: # of Closed Stores | E13: =E9 -> 67 | F13: =F9 -> 101 | G13: =G9 -> 97 | H13: =H9 -> 65 | I13: =I9 -> 105 | J13: =J9 -> 92 | K13: =K9 -> 95 | L13: =L9 -> 100 | ... S13: =S9 -> 70
B14: Closed Stores Proportion | E14: =E13/E11 -> 0.0043591412 | F14: =F13/F11 -> 0.0062046935 | G14: =G13/G11 -> 0.0056470862 | H14: =H13/H11 -> 0.0035852179 | I14: =I13/I11 -> 0.0054962312 | J14: =J13/J11 -> 0.0046032223 | K14: =K13/K11 -> 0.004554389 | L14: =L13/L11 -> 0.0045968558 | ... S14: =S13/S11 -> 0.0023844398
B15: # of Ending Stores | E15: =E11+E12-E13 -> 16278 | F15: =F11+F12-F13 -> 17177 | G15: =G11+G12-G13 -> 18130 | H15: =H11+H12-H13 -> 19104 | I15: =I11+I12-I13 -> 19986 | J15: =J11+J12-J13 -> 20859 | K15: =K11+K12-K13 -> 21754 | L15: =L11+L12-L13 -> 22689 | ... S15: =S11+S12-S13 -> 30682
B16: Growth Rate in # of Stores | E16: - | F16: =(F15-E15)/E15 -> 0.055227915 | G16: =(G15-F15)/F15 -> 0.055481167 | H16: =(H15-G15)/G15 -> 0.053723111 | I16: =(I15-H15)/H15 -> 0.046168342 | J16: =(J15-I15)/I15 -> 0.043680576 | K16: =(K15-J15)/J15 -> 0.042907138 | L16: =(L15-K15)/K15 -> 0.042980601 | M16: =(M15-L15)/L15 -> 0.042972365 | ... S16: =(S15-R15)/R15 -> 0.04513404
B17: Selling Square Footage (in thousands) | E17: 120342 | F17: 127056 | G17: 134532 | H17: 142987 | I17: 151095 | J17: =ROUND(I17*(1+J18), 0) -> 160161 | K17: =ROUND(J17*(1+K18), 0) -> 170571 | L17: =ROUND(K17*(1+L18), 0) -> 182170 | M17: =ROUND(L17*(1+M18), 0) -> 194558 | N17: =ROUND(M17*(1+N18), 0) -> 207204 | O17: =ROUND(N17*(1+O18), 0) -> 220051 | P17: =ROUND(O17*(1+P18), 0) -> 232814 | Q17: =ROUND(P17*(1+Q18), 0) -> 244455 | ... S17: =ROUND(R17*(1+S18), 0) -> 267156
B18: Growth Rate of Selling Square Footage | E18: - | F18: 0.056 | G18: 0.059 | H18: 0.063 | I18: 0.057 | J18: 0.06 | K18: 0.065 | L18: 0.068 | M18: 0.068 | N18: 0.065 | O18: 0.062 | P18: 0.058 | Q18: 0.05 | R18: 0.0455 | S18: 0.0453
B19: Average Square Foot per Store | E19: =ROUND((E17/E15)*1000, 0) -> 7393 | F19: =ROUND((F17/F15)*1000, 0) -> 7397 | G19: =ROUND((G17/G15)*1000, 0) -> 7420 | H19: =ROUND((H17/H15)*1000, 0) -> 7485 | I19: =ROUND((I17/I15)*1000, 0) -> 7560 | J19: =ROUND((J17/J15)*1000, 0) -> 7678 | K19: =ROUND((K17/K15)*1000, 0) -> 7841 | L19: =ROUND((L17/L15)*1000, 0) -> 8029 | ... S19: =ROUND((S17/S15)*1000, 0) -> 8707
B20: Growth Rate of Average Square Foot per Store | E20: - | F20: =(F19-E19)/E19 -> 0.00054105235 | G20: =(G19-F19)/F19 -> 0.0031093687 | H20: =(H19-G19)/G19 -> 0.0087601078 | I20: =(I19-H19)/H19 -> 0.01002004 | J20: =(J19-I19)/I19 -> 0.015608466 | K20: =(K19-J19)/J19 -> 0.021229487 | L20: =(L19-K19)/K19 -> 0.023976534 | M20: =(M19-L19)/L19 -> 0.024037863 | ... S20: =(S19-R19)/R19 -> 0.00011486331
B21: Average Sales per Square Foot | E21: 237 | F21: 273 | G21: 262 | H21: 273 | I21: 264 | J21: 267 | K21: 269 | L21: 271 | M21: 271 | N21: 274 | O21: 272 | P21: 273 | Q21: 272 | R21: 274 | S21: 273
B22: Growth Rate of Average Sales per Square Foot | E22: - | F22: =(F21-E21)/E21 -> 0.15189873 | G22: =(G21-F21)/F21 -> -0.04029304 | H22: =(H21-G21)/G21 -> 0.041984733 | I22: =(I21-H21)/H21 -> -0.032967033 | J22: =(J21-I21)/I21 -> 0.011363636 | K22: =(K21-J21)/J21 -> 0.0074906367 | L22: =(L21-K21)/K21 -> 0.0074349442 | M22: =(M21-L21)/L21 -> 0 | ... S22: =(S21-R21)/R21 -> -0.003649635
B23: Revenue Projections | J23: =J19*J15*J21 -> 42761492334 | K23: =K19*K15*K21 -> 45884167666 | L23: =L19*L15*L21 -> 49368064851 | M23: =M19*M15*M21 -> 52727225568 | N23: =N19*N15*N21 -> 56770819254 | O23: =O19*O15*O21 -> 59853967200 | P23: =P19*P15*P21 -> 63559589184 | Q23: =Q19*Q15*Q21 -> 66491436320 | ... S23: =S19*S15*S21 -> 72931451502
B28: Total Revenue | E28: 27754 | F28: 33746.8 | G28: 34220.4 | H28: 37844.9 | I28: 38691.6 | J28: =J23/1000000 -> 42761.492 | K28: =K23/1000000 -> 45884.168 | L28: =L23/1000000 -> 49368.065 | M28: =M23/1000000 -> 52727.226 | N28: =N23/1000000 -> 56770.819 | O28: =O23/1000000 -> 59853.967 | P28: =P23/1000000 -> 63559.589 | Q28: =Q23/1000000 -> 66491.436 | ... S28: =S23/1000000 -> 72931.452
B29: Growth Rate of Total Revenue | E29: - | F29: =(F28-E28)/E28 -> 0.21592563 | G29: =(G28-F28)/F28 -> 0.014033923 | H29: =(H28-G28)/G28 -> 0.10591635 | I29: =(I28-H28)/H28 -> 0.022372896 | J29: =(J28-I28)/I28 -> 0.10518801 | K29: =(K28-J28)/J28 -> 0.073025406 | L29: =(L28-K28)/K28 -> 0.075928089 | M29: =(M28-L28)/L28 -> 0.068043192 | ... S29: =(S28-R28)/R28 -> 0.041439291
B30: COGS + Operating Costs | E30: =(1-0.32)*E28 -> 18872.72 | F30: =(1-0.32)*F28 -> 22947.824 | G30: =(1-0.32)*G28 -> 23269.872 | H30: =(1-0.32)*H28 -> 25734.532 | I30: =(1-0.32)*I28 -> 26310.288 | J30: =(1-0.32)*J28 -> 29077.815 | K30: =(1-0.32)*K28 -> 31201.234 | L30: =(1-0.32)*L28 -> 33570.284 | ... S30: =(1-0.32)*S28 -> 49593.387
B31: Total Store Sales by Segment
B32: % Sales of Consumables | E32: 0.78 | F32: 0.768 | G32: 0.767 | H32: 0.797 | I32: 0.81 | J32: 0.81 | K32: 0.81 | L32: 0.815 | M32: 0.815 | N32: 0.82
B33: Growth Rate of Consumables Sales | E33: - | F33: =(F32-E32)/E32 -> -0.015384615 | G33: =(G32-F32)/F32 -> -0.0013020833 | H33: =(H32-G32)/G32 -> 0.039113429 | I33: =(I32-H32)/H32 -> 0.016311167 | J33: =(J32-I32)/I32 -> 0 | K33: =(K32-J32)/J32 -> 0 | L33: =(L32-K32)/K32 -> 0.0061728395 | M33: =(M32-L32)/L32 -> 0 | N33: =(N32-M32)/M32 -> 0.0061349693
B34: % Sales of Seasonal | E34: 0.117 | F34: 0.121 | G34: 0.122 | H34: 0.11 | I34: 0.106 | J34: 0.105 | K34: 0.105 | L34: 0.1 | M34: 0.1 | N34: 0.095
B35: Growth Rate of Seasonal Sales | E35: - | F35: =(F34-E34)/E34 -> 0.034188034 | G35: =(G34-F34)/F34 -> 0.0082644628 | H35: =(H34-G34)/G34 -> -0.098360656 | I35: =(I34-H34)/H34 -> -0.036363636 | J35: =(J34-I34)/I34 -> -0.0094339623 | K35: =(K34-J34)/J34 -> 0 | L35: =(L34-K34)/K34 -> -0.047619048 | M35: =(M34-L34)/L34 -> 0 | N35: =(N34-M34)/M34 -> -0.05
B36: % Sales of Home Products | E36: 0.058 | F36: 0.065 | G36: 0.068 | H36: 0.062 | I36: 0.056 | J36: 0.055 | K36: 0.055 | L36: 0.053 | M36: 0.051 | N36: 0.051
B37: Growth Rate of Home Products Sales | E37: - | F37: =(F36-E36)/E36 -> 0.12068966 | G37: =(G36-F36)/F36 -> 0.046153846 | H37: =(H36-G36)/G36 -> -0.088235294 | I37: =(I36-H36)/H36 -> -0.096774194 | J37: =(J36-I36)/I36 -> -0.017857143 | K37: =(K36-J36)/J36 -> 0 | L37: =(L36-K36)/K36 -> -0.036363636 | M37: =(M36-L36)/L36 -> -0.037735849 | N37: =(N36-M36)/M36 -> 0
B38: % Sales of Apparel | E38: 0.045 | F38: 0.046 | G38: 0.043 | H38: 0.031 | I38: 0.028 | J38: =1-J36-J34-J32 -> 0.03 | K38: =1-K36-K34-K32 -> 0.03 | L38: =1-L36-L34-L32 -> 0.032 | M38: =1-M36-M34-M32 -> 0.034 | N38: =1-N36-N34-N32 -> 0.034
B39: Growth Rate of Apparel Sales | E39: - | F39: =(F38-E38)/E38 -> 0.022222222 | G39: =(G38-F38)/F38 -> -0.065217391 | H39: =(H38-G38)/G38 -> -0.27906977 | I39: =(I38-H38)/H38 -> -0.096774194 | J39: =(J38-I38)/I38 -> 0.071428571 | K39: =(K38-J38)/J38 -> 0 | L39: =(L38-K38)/K38 -> 0.066666667 | M39: =(M38-L38)/L38 -> 0.0625 | N39: =(N38-M38)/M38 -> 0

Sheet DCF (Bull Case)
A1: All numbers in millions of dollars. | B1: Historical | G1: Projected
A2: Year | B2: 2019 | C2: 2020 | D2: 2021 | E2: 2022 | F2: 2023 | G2: 2024 | H2: 2025 | I2: 2026 | J2: 2027 | K2: 2028 | L2: 2029 | M2: 2030 | N2: 2031 | O2: 2032 | P2: 2033
A3: Revenue | B3: ='Revenue Build (Base Case)'!E28 -> 27754 | C3: ='Revenue Build (Base Case)'!F28 -> 33746.8 | D3: ='Revenue Build (Base Case)'!G28 -> 34220.4 | E3: ='Revenue Build (Base Case)'!H28 -> 37844.9 | F3: ='Revenue Build (Base Case)'!I28 -> 38691.6 | G3: ='Revenue Build (Bull Case)'!J28 -> 42761.492 | H3: ='Revenue Build (Bull Case)'!K28 -> 45884.168 | I3: ='Revenue Build (Bull Case)'!L28 -> 49368.065 | J3: ='Revenue Build (Bull Case)'!M28 -> 52727.226 | K3: ='Revenue Build (Bull Case)'!N28 -> 56770.819 | L3: ='Revenue Build (Bull Case)'!O28 -> 59853.967 | M3: ='Revenue Build (Bull Case)'!P28 -> 63559.589 | N3: ='Revenue Build (Bull Case)'!Q28 -> 66491.436 | ... P3: ='Revenue Build (Bull Case)'!S28 -> 72931.452
A4: revenue growth | B4: 0.083 | C4: 0.216 | D4: 0.014 | E4: 0.106 | F4: 0.022 | G4: =(G3-F3)/F3 -> 0.10518801 | H4: =(H3-G3)/G3 -> 0.073025406 | I4: =(I3-H3)/H3 -> 0.075928089 | J4: =(J3-I3)/I3 -> 0.068043192 | K4: =(K3-J3)/J3 -> 0.076688914 | L4: =(L3-K3)/K3 -> 0.054308675 | M4: =(M3-L3)/L3 -> 0.06191105 | N4: =(N3-M3)/M3 -> 0.046127534 | ... P4: =(P3-O3)/O3 -> 0.041439291
A5: EBIT | B5: 2336.9 | C5: 3557.5 | D5: 3223.3 | E5: 3330.4 | F5: 2453 | G5: =G3*G6 -> 2856.4677 | H5: =H3*H6 -> 3065.0624 | I5: =I3*I6 -> 3544.6271 | J5: =J3*J6 -> 4049.4509 | K5: =K3*K6 -> 4927.7071 | L5: =L3*L6 -> 5494.5942 | M5: =M3*M6 -> 5834.7703 | N5: =N3*N6 -> 6183.7036 | ... P5: =P3*P6 -> 6928.4879
A6: %rev | B6: 0.084 | C6: 0.105 | D6: 0.094 | E6: 0.088 | F6: 0.063 | G6: =AVERAGE(B6:F6)-0.02 -> 0.0668 | H6: =G6 -> 0.0668 | I6: =H6+0.005 -> 0.0718 | J6: =I6+0.005 -> 0.0768 | K6: 0.0868 | L6: 0.0918 | M6: 0.0918 | N6: 0.093 | O6: 0.095 | P6: 0.095
A7: NOPAT | B7: =B5*(1-$B23) -> 2230.1037 | C7: =C5*(1-$B23) -> 3394.9223 | D7: =D5*(1-$B23) -> 3075.9952 | E7: =E5*(1-$B23) -> 3178.2007 | F7: =F5*(1-$B23) -> 2340.8979 | G7: =G5*(1-$B25) -> 2239.4707 | H7: =H5*(1-$B25) -> 2403.0089 | I7: =I5*(1-$B25) -> 2778.9876 | J7: =J5*(1-$B25) -> 3174.7695 | K7: =K5*(1-$B25) -> 3863.3224 | L7: =L5*(1-$B25) -> 4307.7618 | M7: =M5*(1-$B25) -> 4574.4599 | N7: =N5*(1-$B25) -> 4848.0236 | ... P7: =P5*(1-$B25) -> 5431.9345
A8: %rev | B8: =B7/B3 -> 0.080352514 | C8: =C7/C3 -> 0.10059983 | D8: =D7/D3 -> 0.089887763 | E8: =E7/E3 -> 0.083979631 | F8: =F7/F3 -> 0.06050145 | G8: =G7/G3 -> 0.0523712 | H8: =H7/H3 -> 0.0523712 | I8: =I7/I3 -> 0.0562912 | ... P8: =P7/P3 -> 0.07448
A9: (+) D&A | B9: 504.8 | C9: 574.2 | D9: 641.3 | E9: 724.9 | F9: 848.8 | G9: =G10*G3 -> 2095.6182 | H9: =H10*H3 -> 2248.6516 | I9: =I10*I3 -> 2221.5629 | J9: =J10*J3 -> 2372.7252 | K9: =K10*K3 -> 2668.2285 | L9: =L10*L3 -> 2932.8444 | M9: =M10*M3 -> 3177.9795 | N9: =N10*N3 -> 3058.6061 | ... P9: =P10*P3 -> 2917.2581
A10: %rev | B10: =B9/B3 -> 0.018188369 | C10: =C9/C3 -> 0.017014947 | D10: =D9/D3 -> 0.018740284 | E10: =E9/E3 -> 0.019154496 | F10: =F9/F3 -> 0.021937578 | G10: =AVERAGE(B10:F10)+0.03 -> 0.049007135 | H10: =AVERAGE(B10:F10)+0.03 -> 0.049007135 | I10: 0.045 | J10: 0.045 | K10: 0.047 | L10: 0.049 | M10: 0.05 | N10: 0.046 | O10: 0.043 | P10: 0.04
A11: (-) CapEx | B11: -784.8 | C11: -1028 | D11: -1070.5 | E11: -1560.6 | F11: -1700.2 | G11: =G12*G3 -> -2779.497 | H11: =H12*H3 -> -2982.4709 | I11: =I12*I3 -> -2942.3419 | J11: =J12*J3 -> -3378.4883 | K11: =K12*K3 -> -3285.7047 | L11: =L12*L3 -> -2992.6984 | M11: =M12*M3 -> -3177.9795 | N11: =N12*N3 -> -3191.5889 | ... P11: =P12*P3 -> -2917.2581
A12: %rev | B12: =B11/B3 -> -0.028277005 | C12: =C11/C3 -> -0.030462148 | D12: =D11/D3 -> -0.03128251 | E12: =E11/E3 -> -0.041236732 | F12: =F11/F3 -> -0.043942354 | G12: -0.065 | H12: -0.065 | I12: =AVERAGE(B12:H12)-0.016 -> -0.059600107 | J12: =AVERAGE(C12:I12)-0.016 -> -0.064074836 | K12: =AVERAGE(D12:J12)-0.005 -> -0.057876648 | L12: -0.05 | M12: -0.05 | N12: -0.048 | O12: -0.046 | P12: -0.04
A13: NWC | B13: ='NWC Build'!E20 -> 394.543 | C13: ='NWC Build'!F20 -> -173.141 | D13: ='NWC Build'!G20 -> -20.343 | E13: ='NWC Build'!H20 -> 1311.665 | F13: ='NWC Build'!I20 -> 1516.385 | G13: ='NWC Build'!J20 -> 262.65366 | H13: ='NWC Build'!K20 -> -164.98008 | I13: ='NWC Build'!L20 -> 160.1978 | ... P13: ='NWC Build'!S20 -> 250.50904
A14: %rev | B14: =B13/B3 -> 0.014215717 | C14: =C13/C3 -> -0.0051305902 | D14: =D13/D3 -> -0.00059446997 | E14: =E13/E3 -> 0.034658963 | F14: =F13/F3 -> 0.039191582 | G14: =G13/G3 -> 0.0061422941 | H14: =H13/H3 -> -0.0035955774 | I14: =I13/I3 -> 0.0032449681 | ... P14: =P13/P3 -> 0.0034348561
A15: Change in NWC | B15: 0 | C15: =C13-B13 -> -567.684 | D15: =D13-C13 -> 152.798 | E15: =E13-D13 -> 1332.008 | F15: =F13-E13 -> 204.72 | G15: =G13-F13 -> -1253.7313 | H15: =H13-G13 -> -427.63374 | I15: =I13-H13 -> 325.17787 | J15: =J13-I13 -> 248.43336 | ... P15: =P13-O13 -> 191.94798
A16: FCF | B16: 0 | C16: =C7+C9+C11-C15 -> 3508.8063 | D16: =D7+D9+D11-D15 -> 2493.9972 | E16: =E7+E9+E11-E15 -> 1010.4927 | F16: =F7+F9+F11-F15 -> 1284.7779 | G16: =G7+G9+G11-G15 -> 2809.3232 | H16: =H7+H9+H11-H15 -> 2096.8234 | I16: =I7+I9+I11-I15 -> 1733.0307 | J16: =J7+J9+J11-J15 -> 1920.573 | ... P16: =P7+P9+P11-P15 -> 5239.9865
